Workbook

Sheet Sheet1
A1: ItemLocator | B1: Fecha | C1: TAC | D1: Item | E1: Locator | F1: Sublocator | G1: UOM | H1: FISICO | I1: on hand qty | J1: diferencia | K1: porcentaje | L1: Comments | M1: Location Validated | N1: Dollar U | O1: Total
A2: =_xlfn.CONCAT(D2,E2) -> RS-2090MONCOILS | B2: 46041 | C2: 16 | D2: RS-2090 | E2: MONCOILS | F2: MONCOILS.. | G2: FT | H2: 0 | I2: 0.001 | J2: =Table1[[#This Row],[FISICO]]-Table1[[#This Row],[on hand qty]] -> -0.001 | K2: =IFERROR(IF((I2/H2)<1,I2/H2, H2/I2), 0) -> 0 | L2: =IF(Table1[[#This Row],[FISICO]]="",Sheet2!$A$7,IF(Table1[[#This Row],[diferencia]]=0,Sheet2!$A$9,Sheet2!$A$6)) -> NOT Accuracy Inventory | M2: =E2 -> MONCOILS | N2: =_xlfn.XLOOKUP(Table1[[#This Row],[ItemLocator]], [1]Data!$A:$A,[1]Data!$R:$R,0,0) -> 2.54377 | O2: =Table1[[#This Row],[Dollar U]]*Table1[[#This Row],[diferencia]] -> -0.00254377
A3: =_xlfn.CONCAT(D3,E3) -> 306813P8MONCON | B3: 46041 | C3: 17 | D3: 306813P8 | E3: MONCON | F3: MONCON.. | G3: EA | H3: 1 | I3: 1 | J3: =Table1[[#This Row],[FISICO]]-Table1[[#This Row],[on hand qty]] -> 0 | K3: =IFERROR(IF((I3/H3)<1,I3/H3, H3/I3), 0) -> 1 | L3: =IF(Table1[[#This Row],[FISICO]]="",Sheet2!$A$7,IF(Table1[[#This Row],[diferencia]]=0,Sheet2!$A$9,Sheet2!$A$6)) -> OK Accuracy | M3: =E3 -> MONCON | N3: =_xlfn.XLOOKUP(Table1[[#This Row],[ItemLocator]], [1]Data!$A:$A,[1]Data!$R:$R,0,0) -> 439.13405 | O3: =Table1[[#This Row],[Dollar U]]*Table1[[#This Row],[diferencia]] -> 0
A4: =_xlfn.CONCAT(D4,E4) -> 329483P1MONCON | B4: 46041 | C4: 18 | D4: 329483P1 | E4: MONCON | F4: MONCON.. | G4: EA | H4: 38 | I4: 1 | J4: =Table1[[#This Row],[FISICO]]-Table1[[#This Row],[on hand qty]] -> 37 | K4: =IFERROR(IF((I4/H4)<1,I4/H4, H4/I4), 0) -> 0.026315789 | L4: =IF(Table1[[#This Row],[FISICO]]="",Sheet2!$A$7,IF(Table1[[#This Row],[diferencia]]=0,Sheet2!$A$9,Sheet2!$A$6)) -> NOT Accuracy Inventory | M4: =E4 -> MONCON | N4: =_xlfn.XLOOKUP(Table1[[#This Row],[ItemLocator]], [1]Data!$A:$A,[1]Data!$R:$R,0,0) -> 8.69167 | O4: =Table1[[#This Row],[Dollar U]]*Table1[[#This Row],[diferencia]] -> 321.59179
A5: =_xlfn.CONCAT(D5,E5) -> 122545P2MONDA | B5: 46041 | C5: 20 | D5: 122545P2 | E5: MONDA | F5: MONDA.. | G5: EA | H5: 259 | I5: 259 | J5: =Table1[[#This Row],[FISICO]]-Table1[[#This Row],[on hand qty]] -> 0 | K5: =IFERROR(IF((I5/H5)<1,I5/H5, H5/I5), 0) -> 1 | L5: =IF(Table1[[#This Row],[FISICO]]="",Sheet2!$A$7,IF(Table1[[#This Row],[diferencia]]=0,Sheet2!$A$9,Sheet2!$A$6)) -> OK Accuracy | M5: =E5 -> MONDA | N5: =_xlfn.XLOOKUP(Table1[[#This Row],[ItemLocator]], [1]Data!$A:$A,[1]Data!$R:$R,0,0) -> 0.14313 | O5: =Table1[[#This Row],[Dollar U]]*Table1[[#This Row],[diferencia]] -> 0
A6: =_xlfn.CONCAT(D6,E6) -> 176125P1MONDA | B6: 46041 | C6: 21 | D6: 176125P1 | E6: MONDA | F6: MONDA.. | G6: EA | H6: 1 | I6: 1 | J6: =Table1[[#This Row],[FISICO]]-Table1[[#This Row],[on hand qty]] -> 0 | K6: =IFERROR(IF((I6/H6)<1,I6/H6, H6/I6), 0) -> 1 | L6: =IF(Table1[[#This Row],[FISICO]]="",Sheet2!$A$7,IF(Table1[[#This Row],[diferencia]]=0,Sheet2!$A$9,Sheet2!$A$6)) -> OK Accuracy | M6: =E6 -> MONDA | N6: =_xlfn.XLOOKUP(Table1[[#This Row],[ItemLocator]], [1]Data!$A:$A,[1]Data!$R:$R,0,0) -> 64.39542 | O6: =Table1[[#This Row],[Dollar U]]*Table1[[#This Row],[diferencia]] -> 0
A7: =_xlfn.CONCAT(D7,E7) -> 178339P1MONDA | B7: 46041 | C7: 22 | D7: 178339P1 | E7: MONDA | F7: MONDA.. | G7: EA | H7: 30 | I7: 34 | J7: =Table1[[#This Row],[FISICO]]-Table1[[#This Row],[on hand qty]] -> -4 | K7: =IFERROR(IF((I7/H7)<1,I7/H7, H7/I7), 0) -> 0.88235294 | L7: =IF(Table1[[#This Row],[FISICO]]="",Sheet2!$A$7,IF(Table1[[#This Row],[diferencia]]=0,Sheet2!$A$9,Sheet2!$A$6)) -> NOT Accuracy Inventory | M7: =E7 -> MONDA | N7: =_xlfn.XLOOKUP(Table1[[#This Row],[ItemLocator]], [1]Data!$A:$A,[1]Data!$R:$R,0,0) -> 4.82421 | O7: =Table1[[#This Row],[Dollar U]]*Table1[[#This Row],[diferencia]] -> -19.29684
A8: =_xlfn.CONCAT(D8,E8) -> 310623P1MONDA | B8: 46041 | C8: 23 | D8: 310623P1 | E8: MONDA | F8: MONDA.. | G8: EA | H8: 85 | I8: 85 | J8: =Table1[[#This Row],[FISICO]]-Table1[[#This Row],[on hand qty]] -> 0 | K8: =IFERROR(IF((I8/H8)<1,I8/H8, H8/I8), 0) -> 1 | L8: =IF(Table1[[#This Row],[FISICO]]="",Sheet2!$A$7,IF(Table1[[#This Row],[diferencia]]=0,Sheet2!$A$9,Sheet2!$A$6)) -> OK Accuracy | M8: =E8 -> MONDA | N8: =_xlfn.XLOOKUP(Table1[[#This Row],[ItemLocator]], [1]Data!$A:$A,[1]Data!$R:$R,0,0) -> 0.75218 | O8: =Table1[[#This Row],[Dollar U]]*Table1[[#This Row],[diferencia]] -> 0
A9: =_xlfn.CONCAT(D9,E9) -> 345066G1MONDA | B9: 46041 | C9: 24 | D9: 345066G1 | E9: MONDA | F9: MONDA.. | G9: EA | H9: 13 | I9: 13 | J9: =Table1[[#This Row],[FISICO]]-Table1[[#This Row],[on hand qty]] -> 0 | K9: =IFERROR(IF((I9/H9)<1,I9/H9, H9/I9), 0) -> 1 | L9: =IF(Table1[[#This Row],[FISICO]]="",Sheet2!$A$7,IF(Table1[[#This Row],[diferencia]]=0,Sheet2!$A$9,Sheet2!$A$6)) -> OK Accuracy | M9: =E9 -> MONDA | N9: =_xlfn.XLOOKUP(Table1[[#This Row],[ItemLocator]], [1]Data!$A:$A,[1]Data!$R:$R,0,0) -> 2491.3911 | O9: =Table1[[#This Row],[Dollar U]]*Table1[[#This Row],[diferencia]] -> 0
A10: =_xlfn.CONCAT(D10,E10) -> 1C26657P1MONPLENUM | B10: 46041 | C10: 120 | D10: 1C26657P1 | E10: MONPLENUM | F10: MONPLENUM.. | G10: EA | H10: 56 | I10: 56 | J10: =Table1[[#This Row],[FISICO]]-Table1[[#This Row],[on hand qty]] -> 0 | K10: =IFERROR(IF((I10/H10)<1,I10/H10, H10/I10), 0) -> 1 | L10: =IF(Table1[[#This Row],[FISICO]]="",Sheet2!$A$7,IF(Table1[[#This Row],[diferencia]]=0,Sheet2!$A$9,Sheet2!$A$6)) -> OK Accuracy | M10: =E10 -> MONPLENUM | N10: =_xlfn.XLOOKUP(Table1[[#This Row],[ItemLocator]], [1]Data!$A:$A,[1]Data!$R:$R,0,0) -> 0.8364 | O10: =Table1[[#This Row],[Dollar U]]*Table1[[#This Row],[diferencia]] -> 0
A11: =_xlfn.CONCAT(D11,E11) -> 201769P2MONPLENUM | B11: 46041 | C11: 121 | D11: 201769P2 | E11: MONPLENUM | F11: MONPLENUM.. | G11: EA | H11: 68 | I11: 66 | J11: =Table1[[#This Row],[FISICO]]-Table1[[#This Row],[on hand qty]] -> 2 | K11: =IFERROR(IF((I11/H11)<1,I11/H11, H11/I11), 0) -> 0.97058824 | L11: =IF(Table1[[#This Row],[FISICO]]="",Sheet2!$A$7,IF(Table1[[#This Row],[diferencia]]=0,Sheet2!$A$9,Sheet2!$A$6)) -> NOT Accuracy Inventory | M11: =E11 -> MONPLENUM | N11: =_xlfn.XLOOKUP(Table1[[#This Row],[ItemLocator]], [1]Data!$A:$A,[1]Data!$R:$R,0,0) -> 9.32485 | O11: =Table1[[#This Row],[Dollar U]]*Table1[[#This Row],[diferencia]] -> 18.6497
A12: =_xlfn.CONCAT(D12,E12) -> 322162P2MONPLENUM | B12: 46041 | C12: 122 | D12: 322162P2 | E12: MONPLENUM | F12: MONPLENUM.. | G12: EA | H12: 55 | I12: 55 | J12: =Table1[[#This Row],[FISICO]]-Table1[[#This Row],[on hand qty]] -> 0 | K12: =IFERROR(IF((I12/H12)<1,I12/H12, H12/I12), 0) -> 1 | L12: =IF(Table1[[#This Row],[FISICO]]="",Sheet2!$A$7,IF(Table1[[#This Row],[diferencia]]=0,Sheet2!$A$9,Sheet2!$A$6)) -> OK Accuracy | M12: =E12 -> MONPLENUM | N12: =_xlfn.XLOOKUP(Table1[[#This Row],[ItemLocator]], [1]Data!$A:$A,[1]Data!$R:$R,0,0) -> 455.33434 | O12: =Table1[[#This Row],[Dollar U]]*Table1[[#This Row],[diferencia]] -> 0
A13: =_xlfn.CONCAT(D13,E13) -> 334814P1MONPLENUM | B13: 46041 | C13: 123 | D13: 334814P1 | E13: MONPLENUM | F13: MONPLENUM.. | G13: EA | H13: 66 | I13: 66 | J13: =Table1[[#This Row],[FISICO]]-Table1[[#This Row],[on hand qty]] -> 0 | K13: =IFERROR(IF((I13/H13)<1,I13/H13, H13/I13), 0) -> 1 | L13: =IF(Table1[[#This Row],[FISICO]]="",Sheet2!$A$7,IF(Table1[[#This Row],[diferencia]]=0,Sheet2!$A$9,Sheet2!$A$6)) -> OK Accuracy | M13: =E13 -> MONPLENUM | N13: =_xlfn.XLOOKUP(Table1[[#This Row],[ItemLocator]], [1]Data!$A:$A,[1]Data!$R:$R,0,0) -> 12.17557 | O13: =Table1[[#This Row],[Dollar U]]*Table1[[#This Row],[diferencia]] -> 0
... A19: =_xlfn.CONCAT(D19,E19) -> 09-02EL0Z-11MON-AFC | B19: 46041 | C19: 6 | D19: 09-02EL0Z-11 | E19: MON-AFC | F19: MON-AFC.. | G19: EA | H19: 164 | I19: 164 | J19: =Table1[[#This Row],[FISICO]]-Table1[[#This Row],[on hand qty]] -> 0 | K19: =IFERROR(IF((I19/H19)<1,I19/H19, H19/I19), 0) -> 1 | L19: =IF(Table1[[#This Row],[FISICO]]="",Sheet2!$A$7,IF(Table1[[#This Row],[diferencia]]=0,Sheet2!$A$9,Sheet2!$A$6)) -> OK Accuracy | M19: =E19 -> MON-AFC | N19: =_xlfn.XLOOKUP(Table1[[#This Row],[ItemLocator]], [1]Data!$A:$A,[1]Data!$R:$R,0,0) -> 0.07337 | O19: =Table1[[#This Row],[Dollar U]]*Table1[[#This Row],[diferencia]] -> 0
A20: =_xlfn.CONCAT(D20,E20) -> 10014132MON-AFC | B20: 46041 | C20: 7 | D20: 10014132 | E20: MON-AFC | F20: MON-AFC.. | G20: EA | H20: 184 | I20: 253 | J20: =Table1[[#This Row],[FISICO]]-Table1[[#This Row],[on hand qty]] -> -69 | K20: =IFERROR(IF((I20/H20)<1,I20/H20, H20/I20), 0) -> 0.72727273 | L20: =IF(Table1[[#This Row],[FISICO]]="",Sheet2!$A$7,IF(Table1[[#This Row],[diferencia]]=0,Sheet2!$A$9,Sheet2!$A$6)) -> NOT Accuracy Inventory | M20: =E20 -> MON-AFC | N20: =_xlfn.XLOOKUP(Table1[[#This Row],[ItemLocator]], [1]Data!$A:$A,[1]Data!$R:$R,0,0) -> 0.2083 | O20: =Table1[[#This Row],[Dollar U]]*Table1[[#This Row],[diferencia]] -> -14.3727
A21: =_xlfn.CONCAT(D21,E21) -> 245352300MON-AFC | B21: 46041 | C21: 8 | D21: 245352300 | E21: MON-AFC | F21: MON-AFC.. | G21: EA | H21: 14 | I21: 14 | J21: =Table1[[#This Row],[FISICO]]-Table1[[#This Row],[on hand qty]] -> 0 | K21: =IFERROR(IF((I21/H21)<1,I21/H21, H21/I21), 0) -> 1 | L21: =IF(Table1[[#This Row],[FISICO]]="",Sheet2!$A$7,IF(Table1[[#This Row],[diferencia]]=0,Sheet2!$A$9,Sheet2!$A$6)) -> OK Accuracy | M21: =E21 -> MON-AFC | N21: =_xlfn.XLOOKUP(Table1[[#This Row],[ItemLocator]], [1]Data!$A:$A,[1]Data!$R:$R,0,0) -> 14.31254 | O21: =Table1[[#This Row],[Dollar U]]*Table1[[#This Row],[diferencia]] -> 0
A22: =_xlfn.CONCAT(D22,E22) -> 245354700MON-AFC | B22: 46041 | C22: 9 | D22: 245354700 | E22: MON-AFC | F22: MON-AFC.. | G22: EA | H22: 256 | I22: 256 | J22: =Table1[[#This Row],[FISICO]]-Table1[[#This Row],[on hand qty]] -> 0 | K22: =IFERROR(IF((I22/H22)<1,I22/H22, H22/I22), 0) -> 1 | L22: =IF(Table1[[#This Row],[FISICO]]="",Sheet2!$A$7,IF(Table1[[#This Row],[diferencia]]=0,Sheet2!$A$9,Sheet2!$A$6)) -> OK Accuracy | M22: =E22 -> MON-AFC | N22: =_xlfn.XLOOKUP(Table1[[#This Row],[ItemLocator]], [1]Data!$A:$A,[1]Data!$R:$R,0,0) -> 2.564 | O22: =Table1[[#This Row],[Dollar U]]*Table1[[#This Row],[diferencia]] -> 0
A23: =_xlfn.CONCAT(D23,E23) -> 523024P1MON-AFC | B23: 46041 | C23: 10 | D23: 523024P1 | E23: MON-AFC | F23: MON-AFC.. | G23: EA | H23: 7 | I23: 7 | J23: =Table1[[#This Row],[FISICO]]-Table1[[#This Row],[on hand qty]] -> 0 | K23: =IFERROR(IF((I23/H23)<1,I23/H23, H23/I23), 0) -> 1 | L23: =IF(Table1[[#This Row],[FISICO]]="",Sheet2!$A$7,IF(Table1[[#This Row],[diferencia]]=0,Sheet2!$A$9,Sheet2!$A$6)) -> OK Accuracy | M23: =E23 -> MON-AFC | N23: =_xlfn.XLOOKUP(Table1[[#This Row],[ItemLocator]], [1]Data!$A:$A,[1]Data!$R:$R,0,0) -> 1.66327 | O23: =Table1[[#This Row],[Dollar U]]*Table1[[#This Row],[diferencia]] -> 0
A24: =_xlfn.CONCAT(D24,E24) -> 60010621MON-AFC | B24: 46041 | C24: 11 | D24: 60010621 | E24: MON-AFC | F24: MON-AFC.. | G24: EA | H24: 174 | I24: 174 | J24: =Table1[[#This Row],[FISICO]]-Table1[[#This Row],[on hand qty]] -> 0 | K24: =IFERROR(IF((I24/H24)<1,I24/H24, H24/I24), 0) -> 1 | L24: =IF(Table1[[#This Row],[FISICO]]="",Sheet2!$A$7,IF(Table1[[#This Row],[diferencia]]=0,Sheet2!$A$9,Sheet2!$A$6)) -> OK Accuracy | M24: =E24 -> MON-AFC | N24: =_xlfn.XLOOKUP(Table1[[#This Row],[ItemLocator]], [1]Data!$A:$A,[1]Data!$R:$R,0,0) -> 2.43805 | O24: =Table1[[#This Row],[Dollar U]]*Table1[[#This Row],[diferencia]] -> 0
A25: =_xlfn.CONCAT(D25,E25) -> E-375CMON-AFC | B25: 46041 | C25: 12 | D25: E-375C | E25: MON-AFC | F25: MON-AFC.. | G25: FT | H25: 0 | I25: 200 | J25: =Table1[[#This Row],[FISICO]]-Table1[[#This Row],[on hand qty]] -> -200 | K25: =IFERROR(IF((I25/H25)<1,I25/H25, H25/I25), 0) -> 0 | L25: =IF(Table1[[#This Row],[FISICO]]="",Sheet2!$A$7,IF(Table1[[#This Row],[diferencia]]=0,Sheet2!$A$9,Sheet2!$A$6)) -> NOT Accuracy Inventory | M25: =E25 -> MON-AFC | N25: =_xlfn.XLOOKUP(Table1[[#This Row],[ItemLocator]], [1]Data!$A:$A,[1]Data!$R:$R,0,0) -> 0.07072 | O25: =Table1[[#This Row],[Dollar U]]*Table1[[#This Row],[diferencia]] -> -14.144
A26: =_xlfn.CONCAT(D26,E26) -> 60079762G3MON-AFC | B26: 46041 | C26: CONTEO EXTRA URGENTE | D26: 60079762G3 | E26: MON-AFC | F26: MON-AFC.. | H26: 8 | I26: 5 | J26: =Table1[[#This Row],[FISICO]]-Table1[[#This Row],[on hand qty]] -> 3 | K26: =IFERROR(IF((I26/H26)<1,I26/H26, H26/I26), 0) -> 0.625 | L26: =IF(Table1[[#This Row],[FISICO]]="",Sheet2!$A$7,IF(Table1[[#This Row],[diferencia]]=0,Sheet2!$A$9,Sheet2!$A$6)) -> NOT Accuracy Inventory | M26: =E26 -> MON-AFC | N26: =_xlfn.XLOOKUP(Table1[[#This Row],[ItemLocator]], [1]Data!$A:$A,[1]Data!$R:$R,0,0) -> 312.228 | O26: =Table1[[#This Row],[Dollar U]]*Table1[[#This Row],[diferencia]] -> 936.684
A27: =_xlfn.CONCAT(D27,E27) -> 302011P1MONHRS | B27: 46041 | C27: 74 | D27: 302011P1 | E27: MONHRS | F27: MONHRS.. | G27: EA | H27: 6 | I27: 6 | J27: =Table1[[#This Row],[FISICO]]-Table1[[#This Row],[on hand qty]] -> 0 | K27: =IFERROR(IF((I27/H27)<1,I27/H27, H27/I27), 0) -> 1 | L27: =IF(Table1[[#This Row],[FISICO]]="",Sheet2!$A$7,IF(Table1[[#This Row],[diferencia]]=0,Sheet2!$A$9,Sheet2!$A$6)) -> OK Accuracy | M27: =E27 -> MONHRS | N27: =_xlfn.XLOOKUP(Table1[[#This Row],[ItemLocator]], [1]Data!$A:$A,[1]Data!$R:$R,0,0) -> 16.73004 | O27: =Table1[[#This Row],[Dollar U]]*Table1[[#This Row],[diferencia]] -> 0
A28: =_xlfn.CONCAT(D28,E28) -> 316756P1MONHRS | B28: 46041 | C28: 75 | D28: 316756P1 | E28: MONHRS | F28: MONHRS.. | G28: EA | H28: 23 | I28: 23 | J28: =Table1[[#This Row],[FISICO]]-Table1[[#This Row],[on hand qty]] -> 0 | K28: =IFERROR(IF((I28/H28)<1,I28/H28, H28/I28), 0) -> 1 | L28: =IF(Table1[[#This Row],[FISICO]]="",Sheet2!$A$7,IF(Table1[[#This Row],[diferencia]]=0,Sheet2!$A$9,Sheet2!$A$6)) -> OK Accuracy | M28: =E28 -> MONHRS | N28: =_xlfn.XLOOKUP(Table1[[#This Row],[ItemLocator]], [1]Data!$A:$A,[1]Data!$R:$R,0,0) -> 168.49151 | O28: =Table1[[#This Row],[Dollar U]]*Table1[[#This Row],[diferencia]] -> 0
A29: =_xlfn.CONCAT(D29,E29) -> 306813P8MONSKID | B29: 46041 | C29: 129 | D29: 306813P8 | E29: MONSKID | F29: MONSKID.. | G29: EA | H29: 1 | I29: 1 | J29: =Table1[[#This Row],[FISICO]]-Table1[[#This Row],[on hand qty]] -> 0 | K29: =IFERROR(IF((I29/H29)<1,I29/H29, H29/I29), 0) -> 1 | L29: =IF(Table1[[#This Row],[FISICO]]="",Sheet2!$A$7,IF(Table1[[#This Row],[diferencia]]=0,Sheet2!$A$9,Sheet2!$A$6)) -> OK Accuracy | M29: =E29 -> MONSKID | N29: =_xlfn.XLOOKUP(Table1[[#This Row],[ItemLocator]], [1]Data!$A:$A,[1]Data!$R:$R,0,0) -> 439.13405 | O29: =Table1[[#This Row],[Dollar U]]*Table1[[#This Row],[diferencia]] -> 0
A30: =_xlfn.CONCAT(D30,E30) -> 313075P3MONSKID | B30: 46041 | C30: 130 | D30: 313075P3 | E30: MONSKID | F30: MONSKID.. | G30: EA | H30: 1 | I30: 1 | J30: =Table1[[#This Row],[FISICO]]-Table1[[#This Row],[on hand qty]] -> 0 | K30: =IFERROR(IF((I30/H30)<1,I30/H30, H30/I30), 0) -> 1 | L30: =IF(Table1[[#This Row],[FISICO]]="",Sheet2!$A$7,IF(Table1[[#This Row],[diferencia]]=0,Sheet2!$A$9,Sheet2!$A$6)) -> OK Accuracy | M30: =E30 -> MONSKID | N30: =_xlfn.XLOOKUP(Table1[[#This Row],[ItemLocator]], [1]Data!$A:$A,[1]Data!$R:$R,0,0) -> 43.27534 | O30: =Table1[[#This Row],[Dollar U]]*Table1[[#This Row],[diferencia]] -> 0
A31: =_xlfn.CONCAT(D31,E31) -> 313075P4MONSKID | B31: 46041 | C31: 131 | D31: 313075P4 | E31: MONSKID | F31: MONSKID.. | G31: EA | H31: 2 | I31: 2 | J31: =Table1[[#This Row],[FISICO]]-Table1[[#This Row],[on hand qty]] -> 0 | K31: =IFERROR(IF((I31/H31)<1,I31/H31, H31/I31), 0) -> 1 | L31: =IF(Table1[[#This Row],[FISICO]]="",Sheet2!$A$7,IF(Table1[[#This Row],[diferencia]]=0,Sheet2!$A$9,Sheet2!$A$6)) -> OK Accuracy | M31: =E31 -> MONSKID | N31: =_xlfn.XLOOKUP(Table1[[#This Row],[ItemLocator]], [1]Data!$A:$A,[1]Data!$R:$R,0,0) -> 43.67237 | O31: =Table1[[#This Row],[Dollar U]]*Table1[[#This Row],[diferencia]] -> 0
A32: =_xlfn.CONCAT(D32,E32) -> 316756P1MONSKID | B32: 46041 | C32: 132 | D32: 316756P1 | E32: MONSKID | F32: MONSKID.. | G32: EA | H32: 20 | I32: 20 | J32: =Table1[[#This Row],[FISICO]]-Table1[[#This Row],[on hand qty]] -> 0 | K32: =IFERROR(IF((I32/H32)<1,I32/H32, H32/I32), 0) -> 1 | L32: =IF(Table1[[#This Row],[FISICO]]="",Sheet2!$A$7,IF(Table1[[#This Row],[diferencia]]=0,Sheet2!$A$9,Sheet2!$A$6)) -> OK Accuracy | M32: =E32 -> MONSKID | N32: =_xlfn.XLOOKUP(Table1[[#This Row],[ItemLocator]], [1]Data!$A:$A,[1]Data!$R:$R,0,0) -> 168.49151 | O32: =Table1[[#This Row],[Dollar U]]*Table1[[#This Row],[diferencia]] -> 0
A33: =_xlfn.CONCAT(D33,E33) -> 329483P1MONSKID | B33: 46041 | C33: 133 | D33: 329483P1 | E33: MONSKID | F33: MONSKID.. | G33: EA | H33: 2 | I33: 2 | J33: =Table1[[#This Row],[FISICO]]-Table1[[#This Row],[on hand qty]] -> 0 | K33: =IFERROR(IF((I33/H33)<1,I33/H33, H33/I33), 0) -> 1 | L33: =IF(Table1[[#This Row],[FISICO]]="",Sheet2!$A$7,IF(Table1[[#This Row],[diferencia]]=0,Sheet2!$A$9,Sheet2!$A$6)) -> OK Accuracy | M33: =E33 -> MONSKID | N33: =_xlfn.XLOOKUP(Table1[[#This Row],[ItemLocator]], [1]Data!$A:$A,[1]Data!$R:$R,0,0) -> 8.69167 | O33: =Table1[[#This Row],[Dollar U]]*Table1[[#This Row],[diferencia]] -> 0
A34: =_xlfn.CONCAT(D34,E34) -> 1C26657P1MONXDU100 | B34: 46041 | C34: 138 | D34: 1C26657P1 | E34: MONXDU100 | F34: MONXDU100.. | G34: EA | H34: 105 | I34: 105 | J34: =Table1[[#This Row],[FISICO]]-Table1[[#This Row],[on hand qty]] -> 0 | K34: =IFERROR(IF((I34/H34)<1,I34/H34, H34/I34), 0) -> 1 | L34: =IF(Table1[[#This Row],[FISICO]]="",Sheet2!$A$7,IF(Table1[[#This Row],[diferencia]]=0,Sheet2!$A$9,Sheet2!$A$6)) -> OK Accuracy | M34: =E34 -> MONXDU100 | N34: =_xlfn.XLOOKUP(Table1[[#This Row],[ItemLocator]], [1]Data!$A:$A,[1]Data!$R:$R,0,0) -> 0.8364 | O34: =Table1[[#This Row],[Dollar U]]*Table1[[#This Row],[diferencia]] -> 0
A35: =_xlfn.CONCAT(D35,E35) -> 10-13MK51Z-00MON-PROT | B35: 46041 | C35: 13 | D35: 10-13MK51Z-00 | E35: MON-PROT | F35: MON-PROT.. | G35: EA | I35: 2000 | J35: =Table1[[#This Row],[FISICO]]-Table1[[#This Row],[on hand qty]] -> -2000 | K35: =IFERROR(IF((I35/H35)<1,I35/H35, H35/I35), 0) -> 0 | L35: =IF(Table1[[#This Row],[FISICO]]="",Sheet2!$A$7,IF(Table1[[#This Row],[diferencia]]=0,Sheet2!$A$9,Sheet2!$A$6)) -> NOT Counted | M35: =E35 -> MON-PROT | N35: =_xlfn.XLOOKUP(Table1[[#This Row],[ItemLocator]], [1]Data!$A:$A,[1]Data!$R:$R,0,0) -> 0.16684 | O35: =Table1[[#This Row],[Dollar U]]*Table1[[#This Row],[diferencia]] -> -333.68
A36: =_xlfn.CONCAT(D36,E36) -> SRG12107MON-PROT | B36: 46041 | C36: 14 | D36: SRG12107 | E36: MON-PROT | F36: MON-PROT.. | G36: EA | I36: 28 | J36: =Table1[[#This Row],[FISICO]]-Table1[[#This Row],[on hand qty]] -> -28 | K36: =IFERROR(IF((I36/H36)<1,I36/H36, H36/I36), 0) -> 0 | L36: =IF(Table1[[#This Row],[FISICO]]="",Sheet2!$A$7,IF(Table1[[#This Row],[diferencia]]=0,Sheet2!$A$9,Sheet2!$A$6)) -> NOT Counted | M36: =E36 -> MON-PROT | N36: =_xlfn.XLOOKUP(Table1[[#This Row],[ItemLocator]], [1]Data!$A:$A,[1]Data!$R:$R,0,0) -> 0.03388 | O36: =Table1[[#This Row],[Dollar U]]*Table1[[#This Row],[diferencia]] -> -0.94864
A37: =_xlfn.CONCAT(D37,E37) -> 322162P2MONBLW | B37: 46041 | C37: 15 | D37: 322162P2 | E37: MONBLW | F37: MONBLW.. | G37: EA | I37: 123 | J37: =Table1[[#This Row],[FISICO]]-Table1[[#This Row],[on hand qty]] -> -123 | K37: =IFERROR(IF((I37/H37)<1,I37/H37, H37/I37), 0) -> 0 | L37: =IF(Table1[[#This Row],[FISICO]]="",Sheet2!$A$7,IF(Table1[[#This Row],[diferencia]]=0,Sheet2!$A$9,Sheet2!$A$6)) -> NOT Counted | M37: =E37 -> MONBLW | N37: =_xlfn.XLOOKUP(Table1[[#This Row],[ItemLocator]], [1]Data!$A:$A,[1]Data!$R:$R,0,0) -> 455.33434 | O37: =Table1[[#This Row],[Dollar U]]*Table1[[#This Row],[diferencia]] -> -56006.124
A38: =_xlfn.CONCAT(D38,E38) -> 138203MONCR | B38: 46041 | C38: 19 | D38: 138203 | E38: MONCR | F38: MONCR.. | G38: EA | I38: 32 | J38: =Table1[[#This Row],[FISICO]]-Table1[[#This Row],[on hand qty]] -> -32 | K38: =IFERROR(IF((I38/H38)<1,I38/H38, H38/I38), 0) -> 0 | L38: =IF(Table1[[#This Row],[FISICO]]="",Sheet2!$A$7,IF(Table1[[#This Row],[diferencia]]=0,Sheet2!$A$9,Sheet2!$A$6)) -> NOT Counted | M38: =E38 -> MONCR | N38: =_xlfn.XLOOKUP(Table1[[#This Row],[ItemLocator]], [1]Data!$A:$A,[1]Data!$R:$R,0,0) -> 1.34353 | O38: =Table1[[#This Row],[Dollar U]]*Table1[[#This Row],[diferencia]] -> -42.99296
A39: =_xlfn.CONCAT(D39,E39) -> 09-02EL0Z-11MONDP | B39: 46041 | C39: 25 | D39: 09-02EL0Z-11 | E39: MONDP | F39: MONDP.. | G39: EA | H39: 247 | I39: 247 | J39: =Table1[[#This Row],[FISICO]]-Table1[[#This Row],[on hand qty]] -> 0 | K39: =IFERROR(IF((I39/H39)<1,I39/H39, H39/I39), 0) -> 1 | L39: =IF(Table1[[#This Row],[FISICO]]="",Sheet2!$A$7,IF(Table1[[#This Row],[diferencia]]=0,Sheet2!$A$9,Sheet2!$A$6)) -> OK Accuracy | M39: =E39 -> MONDP | N39: =_xlfn.XLOOKUP(Table1[[#This Row],[ItemLocator]], [1]Data!$A:$A,[1]Data!$R:$R,0,0) -> 0.07337 | O39: =Table1[[#This Row],[Dollar U]]*Table1[[#This Row],[diferencia]] -> 0
A40: =_xlfn.CONCAT(D40,E40) -> 09-02GL0Z-11MONDP | B40: 46041 | C40: 26 | D40: 09-02GL0Z-11 | E40: MONDP | F40: MONDP.. | G40: EA | H40: 247 | I40: 247 | J40: =Table1[[#This Row],[FISICO]]-Table1[[#This Row],[on hand qty]] -> 0 | K40: =IFERROR(IF((I40/H40)<1,I40/H40, H40/I40), 0) -> 1 | L40: =IF(Table1[[#This Row],[FISICO]]="",Sheet2!$A$7,IF(Table1[[#This Row],[diferencia]]=0,Sheet2!$A$9,Sheet2!$A$6)) -> OK Accuracy | M40: =E40 -> MONDP | N40: =_xlfn.XLOOKUP(Table1[[#This Row],[ItemLocator]], [1]Data!$A:$A,[1]Data!$R:$R,0,0) -> 0.40538 | O40: =Table1[[#This Row],[Dollar U]]*Table1[[#This Row],[diferencia]] -> 0
A41: =_xlfn.CONCAT(D41,E41) -> 09-35E00Z-00MONDP | B41: 46041 | C41: 27 | D41: 09-35E00Z-00 | E41: MONDP | F41: MONDP.. | G41: EA | H41: 782 | I41: 782 | J41: =Table1[[#This Row],[FISICO]]-Table1[[#This Row],[on hand qty]] -> 0 | K41: =IFERROR(IF((I41/H41)<1,I41/H41, H41/I41), 0) -> 1 | L41: =IF(Table1[[#This Row],[FISICO]]="",Sheet2!$A$7,IF(Table1[[#This Row],[diferencia]]=0,Sheet2!$A$9,Sheet2!$A$6)) -> OK Accuracy | M41: =E41 -> MONDP | N41: =_xlfn.XLOOKUP(Table1[[#This Row],[ItemLocator]], [1]Data!$A:$A,[1]Data!$R:$R,0,0) -> 0.01907 | O41: =Table1[[#This Row],[Dollar U]]*Table1[[#This Row],[diferencia]] -> 0
A42: =_xlfn.CONCAT(D42,E42) -> 09-39D00Z-A7MONDP | B42: 46041 | C42: 28 | D42: 09-39D00Z-A7 | E42: MONDP | F42: MONDP.. | G42: EA | H42: 1508 | I42: 1508 | J42: =Table1[[#This Row],[FISICO]]-Table1[[#This Row],[on hand qty]] -> 0 | K42: =IFERROR(IF((I42/H42)<1,I42/H42, H42/I42), 0) -> 1 | L42: =IF(Table1[[#This Row],[FISICO]]="",Sheet2!$A$7,IF(Table1[[#This Row],[diferencia]]=0,Sheet2!$A$9,Sheet2!$A$6)) -> OK Accuracy | M42: =E42 -> MONDP | N42: =_xlfn.XLOOKUP(Table1[[#This Row],[ItemLocator]], [1]Data!$A:$A,[1]Data!$R:$R,0,0) -> 0.05175 | O42: =Table1[[#This Row],[Dollar U]]*Table1[[#This Row],[diferencia]] -> 0
A43: =_xlfn.CONCAT(D43,E43) -> 122545P2MONDP | B43: 46041 | C43: 29 | D43: 122545P2 | E43: MONDP | F43: MONDP.. | G43: EA | H43: 850 | I43: 883 | J43: =Table1[[#This Row],[FISICO]]-Table1[[#This Row],[on hand qty]] -> -33 | K43: =IFERROR(IF((I43/H43)<1,I43/H43, H43/I43), 0) -> 0.96262741 | L43: =IF(Table1[[#This Row],[FISICO]]="",Sheet2!$A$7,IF(Table1[[#This Row],[diferencia]]=0,Sheet2!$A$9,Sheet2!$A$6)) -> NOT Accuracy Inventory | M43: =E43 -> MONDP | N43: =_xlfn.XLOOKUP(Table1[[#This Row],[ItemLocator]], [1]Data!$A:$A,[1]Data!$R:$R,0,0) -> 0.14313 | O43: =Table1[[#This Row],[Dollar U]]*Table1[[#This Row],[diferencia]] -> -4.72329
A44: =_xlfn.CONCAT(D44,E44) -> 176125P1MONDP | B44: 46041 | C44: 30 | D44: 176125P1 | E44: MONDP | F44: MONDP.. | G44: EA | H44: 41 | I44: 41 | J44: =Table1[[#This Row],[FISICO]]-Table1[[#This Row],[on hand qty]] -> 0 | K44: =IFERROR(IF((I44/H44)<1,I44/H44, H44/I44), 0) -> 1 | L44: =IF(Table1[[#This Row],[FISICO]]="",Sheet2!$A$7,IF(Table1[[#This Row],[diferencia]]=0,Sheet2!$A$9,Sheet2!$A$6)) -> OK Accuracy | M44: =E44 -> MONDP | N44: =_xlfn.XLOOKUP(Table1[[#This Row],[ItemLocator]], [1]Data!$A:$A,[1]Data!$R:$R,0,0) -> 64.39542 | O44: =Table1[[#This Row],[Dollar U]]*Table1[[#This Row],[diferencia]] -> 0
A45: =_xlfn.CONCAT(D45,E45) -> 333394P2MONDP | B45: 46041 | C45: 31 | D45: 333394P2 | E45: MONDP | F45: MONDP.. | G45: EA | H45: 99 | I45: 99 | J45: =Table1[[#This Row],[FISICO]]-Table1[[#This Row],[on hand qty]] -> 0 | K45: =IFERROR(IF((I45/H45)<1,I45/H45, H45/I45), 0) -> 1 | L45: =IF(Table1[[#This Row],[FISICO]]="",Sheet2!$A$7,IF(Table1[[#This Row],[diferencia]]=0,Sheet2!$A$9,Sheet2!$A$6)) -> OK Accuracy | M45: =E45 -> MONDP | N45: =_xlfn.XLOOKUP(Table1[[#This Row],[ItemLocator]], [1]Data!$A:$A,[1]Data!$R:$R,0,0) -> 30.97366 | O45: =Table1[[#This Row],[Dollar U]]*Table1[[#This Row],[diferencia]] -> 0
...

Sheet Sheet2
A2: Comentarios
A3: Belongs to other Location
A4: Bulk Item Not to be Counted
A5: DH Golden Line Counting
A6: NOT Accuracy Inventory
A7: NOT Counted
A8: Not in BOM / WO
A9: OK Accuracy
A10: Pending Counting
A11: Scrap Not Declared
A13: LINEA
A14: FGEP
... A51: MONSM

Sheet Sheet3
D1: Total | E1: Diferencia | F1: Total | G1: Diferencia | H1: Total | I1: Diferencia | J1: Total | K1: Diferencia | L1: Total | M1: Diferencia | N1: Total | O1: Diferencia | P1: Total | Q1: Diferencia | R1: Total | S1: Diferencia | T1: Total | U1: Diferencia | V1: Total | W1: Diferencia | X1: Total | Y1: Diferencia | Z1: Total | AA1: Diferencia | AB1: Total | AC1: Diferencia | AD1: Total | AE1: Diferencia | AF1: Total | AG1: Diferencia | AH1: Total | AI1: Diferencia | AJ1: Total | AK1: Diferencia | AL1: Total | AM1: Diferencia | AN1: Total | AO1: Diferencia | AP1: Total | AQ1: Diferencia | AR1: Total | AS1: Diferencia | AT1: Total | AU1: Diferencia | AV1: Total | AW1: Diferencia
B2: APU | C2: Location | D2: 46023 | F2: 46024 | H2: 46027 | J2: 46028 | L2: 46029 | N2: 46030 | P2: 46031 | R2: 46034 | T2: 46035 | V2: 46036 | X2: 46037 | Z2: 46038 | AB2: 46041 | AD2: 46042 | AF2: 46043 | AH2: 46044 | AJ2: 46045 | AL2: 46048 | AN2: 46049 | AP2: 46050 | AR2: 46051 | AT2: 46052 | AV2: 46022
A3: MONBLOWR | B3: APU1 | C3: MONBLW | D3: =COUNTIFS(Sheet1!$B:$B, Sheet3!D$2, Sheet1!$M:$M, $C3, Sheet1!$L:$L, Sheet2!$A$6)+COUNTIFS(Sheet1!$B:$B, Sheet3!D$2, Sheet1!$M:$M, $C3, Sheet1!$L:$L, Sheet2!$A$7)+COUNTIFS(Sheet1!$B:$B, Sheet3!D$2, Sheet1!$M:$M, $C3, Sheet1!$L:$L, Sheet2!$A$9) -> 0 | E3: =COUNTIFS(Sheet1!$B:$B, Sheet3!D$2, Sheet1!$M:$M, $C3, Sheet1!$L:$L, Sheet2!$A$6)+COUNTIFS(Sheet1!$B:$B, Sheet3!D$2, Sheet1!$M:$M, $C3, Sheet1!$L:$L, Sheet2!$A$7) -> 0 | F3: =COUNTIFS(Sheet1!$B:$B, Sheet3!F$2, Sheet1!$M:$M, $C3, Sheet1!$L:$L, Sheet2!$A$6)+COUNTIFS(Sheet1!$B:$B, Sheet3!F$2, Sheet1!$M:$M, $C3, Sheet1!$L:$L, Sheet2!$A$7)+COUNTIFS(Sheet1!$B:$B, Sheet3!F$2, Sheet1!$M:$M, $C3, Sheet1!$L:$L, Sheet2!$A$9) -> 0 | G3: =COUNTIFS(Sheet1!$B:$B, Sheet3!F$2, Sheet1!$M:$M, $C3, Sheet1!$L:$L, Sheet2!$A$6)+COUNTIFS(Sheet1!$B:$B, Sheet3!F$2, Sheet1!$M:$M, $C3, Sheet1!$L:$L, Sheet2!$A$7) -> 0 | H3: =COUNTIFS(Sheet1!$B:$B, Sheet3!H$2, Sheet1!$M:$M, $C3, Sheet1!$L:$L, Sheet2!$A$6)+COUNTIFS(Sheet1!$B:$B, Sheet3!H$2, Sheet1!$M:$M, $C3, Sheet1!$L:$L, Sheet2!$A$7)+COUNTIFS(Sheet1!$B:$B, Sheet3!H$2, Sheet1!$M:$M, $C3, Sheet1!$L:$L, Sheet2!$A$9) -> 0 | I3: =COUNTIFS(Sheet1!$B:$B, Sheet3!H$2, Sheet1!$M:$M, $C3, Sheet1!$L:$L, Sheet2!$A$6)+COUNTIFS(Sheet1!$B:$B, Sheet3!H$2, Sheet1!$M:$M, $C3, Sheet1!$L:$L, Sheet2!$A$7) -> 0 | J3: =COUNTIFS(Sheet1!$B:$B, Sheet3!J$2, Sheet1!$M:$M, $C3, Sheet1!$L:$L, Sheet2!$A$6)+COUNTIFS(Sheet1!$B:$B, Sheet3!J$2, Sheet1!$M:$M, $C3, Sheet1!$L:$L, Sheet2!$A$7)+COUNTIFS(Sheet1!$B:$B, Sheet3!J$2, Sheet1!$M:$M, $C3, Sheet1!$L:$L, Sheet2!$A$9) -> 0 | K3: =COUNTIFS(Sheet1!$B:$B, Sheet3!J$2, Sheet1!$M:$M, $C3, Sheet1!$L:$L, Sheet2!$A$6)+COUNTIFS(Sheet1!$B:$B, Sheet3!J$2, Sheet1!$M:$M, $C3, Sheet1!$L:$L, Sheet2!$A$7) -> 0 | L3: =COUNTIFS(Sheet1!$B:$B, Sheet3!L$2, Sheet1!$M:$M, $C3, Sheet1!$L:$L, Sheet2!$A$6)+COUNTIFS(Sheet1!$B:$B, Sheet3!L$2, Sheet1!$M:$M, $C3, Sheet1!$L:$L, Sheet2!$A$7)+COUNTIFS(Sheet1!$B:$B, Sheet3!L$2, Sheet1!$M:$M, $C3, Sheet1!$L:$L, Sheet2!$A$9) -> 0 | M3: =COUNTIFS(Sheet1!$B:$B, Sheet3!L$2, Sheet1!$M:$M, $C3, Sheet1!$L:$L, Sheet2!$A$6)+COUNTIFS(Sheet1!$B:$B, Sheet3!L$2, Sheet1!$M:$M, $C3, Sheet1!$L:$L, Sheet2!$A$7) -> 0 | N3: =COUNTIFS(Sheet1!$B:$B, Sheet3!N$2, Sheet1!$M:$M, $C3, Sheet1!$L:$L, Sheet2!$A$6)+COUNTIFS(Sheet1!$B:$B, Sheet3!N$2, Sheet1!$M:$M, $C3, Sheet1!$L:$L, Sheet2!$A$7)+COUNTIFS(Sheet1!$B:$B, Sheet3!N$2, Sheet1!$M:$M, $C3, Sheet1!$L:$L, Sheet2!$A$9) -> 0 | O3: =COUNTIFS(Sheet1!$B:$B, Sheet3!N$2, Sheet1!$M:$M, $C3, Sheet1!$L:$L, Sheet2!$A$6)+COUNTIFS(Sheet1!$B:$B, Sheet3!N$2, Sheet1!$M:$M, $C3, Sheet1!$L:$L, Sheet2!$A$7) -> 0 | P3: =COUNTIFS(Sheet1!$B:$B, Sheet3!P$2, Sheet1!$M:$M, $C3, Sheet1!$L:$L, Sheet2!$A$6)+COUNTIFS(Sheet1!$B:$B, Sheet3!P$2, Sheet1!$M:$M, $C3, Sheet1!$L:$L, Sheet2!$A$7)+COUNTIFS(Sheet1!$B:$B, Sheet3!P$2, Sheet1!$M:$M, $C3, Sheet1!$L:$L, Sheet2!$A$9) -> 0 | Q3: =COUNTIFS(Sheet1!$B:$B, Sheet3!P$2, Sheet1!$M:$M, $C3, Sheet1!$L:$L, Sheet2!$A$6)+COUNTIFS(Sheet1!$B:$B, Sheet3!P$2, Sheet1!$M:$M, $C3, Sheet1!$L:$L, Sheet2!$A$7) -> 0 | R3: =COUNTIFS(Sheet1!$B:$B, Sheet3!R$2, Sheet1!$M:$M, $C3, Sheet1!$L:$L, Sheet2!$A$6)+COUNTIFS(Sheet1!$B:$B, Sheet3!R$2, Sheet1!$M:$M, $C3, Sheet1!$L:$L, Sheet2!$A$7)+COUNTIFS(Sheet1!$B:$B, Sheet3!R$2, Sheet1!$M:$M, $C3, Sheet1!$L:$L, Sheet2!$A$9) -> 0 | S3: =COUNTIFS(Sheet1!$B:$B, Sheet3!R$2, Sheet1!$M:$M, $C3, Sheet1!$L:$L, Sheet2!$A$6)+COUNTIFS(Sheet1!$B:$B, Sheet3!R$2, Sheet1!$M:$M, $C3, Sheet1!$L:$L, Sheet2!$A$7) -> 0 | T3: =COUNTIFS(Sheet1!$B:$B, Sheet3!T$2, Sheet1!$M:$M, $C3, Sheet1!$L:$L, Sheet2!$A$6)+COUNTIFS(Sheet1!$B:$B, Sheet3!T$2, Sheet1!$M:$M, $C3, Sheet1!$L:$L, Sheet2!$A$7)+COUNTIFS(Sheet1!$B:$B, Sheet3!T$2, Sheet1!$M:$M, $C3, Sheet1!$L:$L, Sheet2!$A$9) -> 0 | U3: =COUNTIFS(Sheet1!$B:$B, Sheet3!T$2, Sheet1!$M:$M, $C3, Sheet1!$L:$L, Sheet2!$A$6)+COUNTIFS(Sheet1!$B:$B, Sheet3!T$2, Sheet1!$M:$M, $C3, Sheet1!$L:$L, Sheet2!$A$7) -> 0 | V3: =COUNTIFS(Sheet1!$B:$B, Sheet3!V$2, Sheet1!$M:$M, $C3, Sheet1!$L:$L, Sheet2!$A$6)+COUNTIFS(Sheet1!$B:$B, Sheet3!V$2, Sheet1!$M:$M, $C3, Sheet1!$L:$L, Sheet2!$A$7)+COUNTIFS(Sheet1!$B:$B, Sheet3!V$2, Sheet1!$M:$M, $C3, Sheet1!$L:$L, Sheet2!$A$9) -> 0 | W3: =COUNTIFS(Sheet1!$B:$B, Sheet3!V$2, Sheet1!$M:$M, $C3, Sheet1!$L:$L, Sheet2!$A$6)+COUNTIFS(Sheet1!$B:$B, Sheet3!V$2, Sheet1!$M:$M, $C3, Sheet1!$L:$L, Sheet2!$A$7) -> 0 | X3: =COUNTIFS(Sheet1!$B:$B, Sheet3!X$2, Sheet1!$M:$M, $C3, Sheet1!$L:$L, Sheet2!$A$6)+COUNTIFS(Sheet1!$B:$B, Sheet3!X$2, Sheet1!$M:$M, $C3, Sheet1!$L:$L, Sheet2!$A$7)+COUNTIFS(Sheet1!$B:$B, Sheet3!X$2, Sheet1!$M:$M, $C3, Sheet1!$L:$L, Sheet2!$A$9) -> 0 | Y3: =COUNTIFS(Sheet1!$B:$B, Sheet3!X$2, Sheet1!$M:$M, $C3, Sheet1!$L:$L, Sheet2!$A$6)+COUNTIFS(Sheet1!$B:$B, Sheet3!X$2, Sheet1!$M:$M, $C3, Sheet1!$L:$L, Sheet2!$A$7) -> 0 | Z3: =COUNTIFS(Sheet1!$B:$B, Sheet3!Z$2, Sheet1!$M:$M, $C3, Sheet1!$L:$L, Sheet2!$A$6)+COUNTIFS(Sheet1!$B:$B, Sheet3!Z$2, Sheet1!$M:$M, $C3, Sheet1!$L:$L, Sheet2!$A$7)+COUNTIFS(Sheet1!$B:$B, Sheet3!Z$2, Sheet1!$M:$M, $C3, Sheet1!$L:$L, Sheet2!$A$9) -> 0 | AA3: =COUNTIFS(Sheet1!$B:$B, Sheet3!Z$2, Sheet1!$M:$M, $C3, Sheet1!$L:$L, Sheet2!$A$6)+COUNTIFS(Sheet1!$B:$B, Sheet3!Z$2, Sheet1!$M:$M, $C3, Sheet1!$L:$L, Sheet2!$A$7) -> 0 | AB3: =COUNTIFS(Sheet1!$B:$B, Sheet3!AB$2, Sheet1!$M:$M, $C3, Sheet1!$L:$L, Sheet2!$A$6)+COUNTIFS(Sheet1!$B:$B, Sheet3!AB$2, Sheet1!$M:$M, $C3, Sheet1!$L:$L, Sheet2!$A$7)+COUNTIFS(Sheet1!$B:$B, Sheet3!AB$2, Sheet1!$M:$M, $C3, Sheet1!$L:$L, Sheet2!$A$9) -> 1 | AC3: =COUNTIFS(Sheet1!$B:$B, Sheet3!AB$2, Sheet1!$M:$M, $C3, Sheet1!$L:$L, Sheet2!$A$6)+COUNTIFS(Sheet1!$B:$B, Sheet3!AB$2, Sheet1!$M:$M, $C3, Sheet1!$L:$L, Sheet2!$A$7) -> 1 | AD3: =COUNTIFS(Sheet1!$B:$B, Sheet3!AD$2, Sheet1!$M:$M, $C3, Sheet1!$L:$L, Sheet2!$A$6)+COUNTIFS(Sheet1!$B:$B, Sheet3!AD$2, Sheet1!$M:$M, $C3, Sheet1!$L:$L, Sheet2!$A$7)+COUNTIFS(Sheet1!$B:$B, Sheet3!AD$2, Sheet1!$M:$M, $C3, Sheet1!$L:$L, Sheet2!$A$9) -> 3 | AE3: =COUNTIFS(Sheet1!$B:$B, Sheet3!AD$2, Sheet1!$M:$M, $C3, Sheet1!$L:$L, Sheet2!$A$6)+COUNTIFS(Sheet1!$B:$B, Sheet3!AD$2, Sheet1!$M:$M, $C3, Sheet1!$L:$L, Sheet2!$A$7) -> 3 | AF3: =COUNTIFS(Sheet1!$B:$B, Sheet3!AF$2, Sheet1!$M:$M, $C3, Sheet1!$L:$L, Sheet2!$A$6)+COUNTIFS(Sheet1!$B:$B, Sheet3!AF$2, Sheet1!$M:$M, $C3, Sheet1!$L:$L, Sheet2!$A$7)+COUNTIFS(Sheet1!$B:$B, Sheet3!AF$2, Sheet1!$M:$M, $C3, Sheet1!$L:$L, Sheet2!$A$9) -> 4 | AG3: =COUNTIFS(Sheet1!$B:$B, Sheet3!AF$2, Sheet1!$M:$M, $C3, Sheet1!$L:$L, Sheet2!$A$6)+COUNTIFS(Sheet1!$B:$B, Sheet3!AF$2, Sheet1!$M:$M, $C3, Sheet1!$L:$L, Sheet2!$A$7) -> 4 | AH3: =COUNTIFS(Sheet1!$B:$B, Sheet3!AH$2, Sheet1!$M:$M, $C3, Sheet1!$L:$L, Sheet2!$A$6)+COUNTIFS(Sheet1!$B:$B, Sheet3!AH$2, Sheet1!$M:$M, $C3, Sheet1!$L:$L, Sheet2!$A$7)+COUNTIFS(Sheet1!$B:$B, Sheet3!AH$2, Sheet1!$M:$M, $C3, Sheet1!$L:$L, Sheet2!$A$9) -> 0 | AI3: =COUNTIFS(Sheet1!$B:$B, Sheet3!AH$2, Sheet1!$M:$M, $C3, Sheet1!$L:$L, Sheet2!$A$6)+COUNTIFS(Sheet1!$B:$B, Sheet3!AH$2, Sheet1!$M:$M, $C3, Sheet1!$L:$L, Sheet2!$A$7) -> 0 | AJ3: =COUNTIFS(Sheet1!$B:$B, Sheet3!AJ$2, Sheet1!$M:$M, $C3, Sheet1!$L:$L, Sheet2!$A$6)+COUNTIFS(Sheet1!$B:$B, Sheet3!AJ$2, Sheet1!$M:$M, $C3, Sheet1!$L:$L, Sheet2!$A$7)+COUNTIFS(Sheet1!$B:$B, Sheet3!AJ$2, Sheet1!$M:$M, $C3, Sheet1!$L:$L, Sheet2!$A$9) -> 0 | AK3: =COUNTIFS(Sheet1!$B:$B, Sheet3!AJ$2, Sheet1!$M:$M, $C3, Sheet1!$L:$L, Sheet2!$A$6)+COUNTIFS(Sheet1!$B:$B, Sheet3!AJ$2, Sheet1!$M:$M, $C3, Sheet1!$L:$L, Sheet2!$A$7) -> 0 | AL3: =COUNTIFS(Sheet1!$B:$B, Sheet3!AL$2, Sheet1!$M:$M, $C3, Sheet1!$L:$L, Sheet2!$A$6)+COUNTIFS(Sheet1!$B:$B, Sheet3!AL$2, Sheet1!$M:$M, $C3, Sheet1!$L:$L, Sheet2!$A$7)+COUNTIFS(Sheet1!$B:$B, Sheet3!AL$2, Sheet1!$M:$M, $C3, Sheet1!$L:$L, Sheet2!$A$9) -> 0 | AM3: =COUNTIFS(Sheet1!$B:$B, Sheet3!AL$2, Sheet1!$M:$M, $C3, Sheet1!$L:$L, Sheet2!$A$6)+COUNTIFS(Sheet1!$B:$B, Sheet3!AL$2, Sheet1!$M:$M, $C3, Sheet1!$L:$L, Sheet2!$A$7) -> 0 | AN3: =COUNTIFS(Sheet1!$B:$B, Sheet3!AN$2, Sheet1!$M:$M, $C3, Sheet1!$L:$L, Sheet2!$A$6)+COUNTIFS(Sheet1!$B:$B, Sheet3!AN$2, Sheet1!$M:$M, $C3, Sheet1!$L:$L, Sheet2!$A$7)+COUNTIFS(Sheet1!$B:$B, Sheet3!AN$2, Sheet1!$M:$M, $C3, Sheet1!$L:$L, Sheet2!$A$9) -> 0 | AO3: =COUNTIFS(Sheet1!$B:$B, Sheet3!AN$2, Sheet1!$M:$M, $C3, Sheet1!$L:$L, Sheet2!$A$6)+COUNTIFS(Sheet1!$B:$B, Sheet3!AN$2, Sheet1!$M:$M, $C3, Sheet1!$L:$L, Sheet2!$A$7) -> 0 | AP3: =COUNTIFS(Sheet1!$B:$B, Sheet3!AP$2, Sheet1!$M:$M, $C3, Sheet1!$L:$L, Sheet2!$A$6)+COUNTIFS(Sheet1!$B:$B, Sheet3!AP$2, Sheet1!$M:$M, $C3, Sheet1!$L:$L, Sheet2!$A$7)+COUNTIFS(Sheet1!$B:$B, Sheet3!AP$2, Sheet1!$M:$M, $C3, Sheet1!$L:$L, Sheet2!$A$9) -> 0 | AQ3: =COUNTIFS(Sheet1!$B:$B, Sheet3!AP$2, Sheet1!$M:$M, $C3, Sheet1!$L:$L, Sheet2!$A$6)+COUNTIFS(Sheet1!$B:$B, Sheet3!AP$2, Sheet1!$M:$M, $C3, Sheet1!$L:$L, Sheet2!$A$7) -> 0 | AR3: =COUNTIFS(Sheet1!$B:$B, Sheet3!AR$2, Sheet1!$M:$M, $C3, Sheet1!$L:$L, Sheet2!$A$6)+COUNTIFS(Sheet1!$B:$B, Sheet3!AR$2, Sheet1!$M:$M, $C3, Sheet1!$L:$L, Sheet2!$A$7)+COUNTIFS(Sheet1!$B:$B, Sheet3!AR$2, Sheet1!$M:$M, $C3, Sheet1!$L:$L, Sheet2!$A$9) -> 0 | AS3: =COUNTIFS(Sheet1!$B:$B, Sheet3!AR$2, Sheet1!$M:$M, $C3, Sheet1!$L:$L, Sheet2!$A$6)+COUNTIFS(Sheet1!$B:$B, Sheet3!AR$2, Sheet1!$M:$M, $C3, Sheet1!$L:$L, Sheet2!$A$7) -> 0 | AT3: =COUNTIFS(Sheet1!$B:$B, Sheet3!AT$2, Sheet1!$M:$M, $C3, Sheet1!$L:$L, Sheet2!$A$6)+COUNTIFS(Sheet1!$B:$B, Sheet3!AT$2, Sheet1!$M:$M, $C3, Sheet1!$L:$L, Sheet2!$A$7)+COUNTIFS(Sheet1!$B:$B, Sheet3!AT$2, Sheet1!$M:$M, $C3, Sheet1!$L:$L, Sheet2!$A$9) -> 0 | AU3: =COUNTIFS(Sheet1!$B:$B, Sheet3!AT$2, Sheet1!$M:$M, $C3, Sheet1!$L:$L, Sheet2!$A$6)+COUNTIFS(Sheet1!$B:$B, Sheet3!AT$2, Sheet1!$M:$M, $C3, Sheet1!$L:$L, Sheet2!$A$7) -> 0 | AV3: =COUNTIFS(Sheet1!$B:$B, Sheet3!AV$2, Sheet1!$M:$M, $C3, Sheet1!$L:$L, Sheet2!$A$6)+COUNTIFS(Sheet1!$B:$B, Sheet3!AV$2, Sheet1!$M:$M, $C3, Sheet1!$L:$L, Sheet2!$A$7)+COUNTIFS(Sheet1!$B:$B, Sheet3!AV$2, Sheet1!$M:$M, $C3, Sheet1!$L:$L, Sheet2!$A$9) -> 0 | AW3: =COUNTIFS(Sheet1!$B:$B, Sheet3!AV$2, Sheet1!$M:$M, $C3, Sheet1!$L:$L, Sheet2!$A$6)+COUNTIFS(Sheet1!$B:$B, Sheet3!AV$2, Sheet1!$M:$M, $C3, Sheet1!$L:$L, Sheet2!$A$7) -> 0
A4: MONCON | B4: APU1 | C4: MONCON | D4: =COUNTIFS(Sheet1!$B:$B, Sheet3!D$2, Sheet1!$M:$M, $C4, Sheet1!$L:$L, Sheet2!$A$6)+COUNTIFS(Sheet1!$B:$B, Sheet3!D$2, Sheet1!$M:$M, $C4, Sheet1!$L:$L, Sheet2!$A$7)+COUNTIFS(Sheet1!$B:$B, Sheet3!D$2, Sheet1!$M:$M, $C4, Sheet1!$L:$L, Sheet2!$A$9) -> 0 | E4: =COUNTIFS(Sheet1!$B:$B, Sheet3!D$2, Sheet1!$M:$M, $C4, Sheet1!$L:$L, Sheet2!$A$6)+COUNTIFS(Sheet1!$B:$B, Sheet3!D$2, Sheet1!$M:$M, $C4, Sheet1!$L:$L, Sheet2!$A$7) -> 0 | F4: =COUNTIFS(Sheet1!$B:$B, Sheet3!F$2, Sheet1!$M:$M, $C4, Sheet1!$L:$L, Sheet2!$A$6)+COUNTIFS(Sheet1!$B:$B, Sheet3!F$2, Sheet1!$M:$M, $C4, Sheet1!$L:$L, Sheet2!$A$7)+COUNTIFS(Sheet1!$B:$B, Sheet3!F$2, Sheet1!$M:$M, $C4, Sheet1!$L:$L, Sheet2!$A$9) -> 0 | G4: =COUNTIFS(Sheet1!$B:$B, Sheet3!F$2, Sheet1!$M:$M, $C4, Sheet1!$L:$L, Sheet2!$A$6)+COUNTIFS(Sheet1!$B:$B, Sheet3!F$2, Sheet1!$M:$M, $C4, Sheet1!$L:$L, Sheet2!$A$7) -> 0 | H4: =COUNTIFS(Sheet1!$B:$B, Sheet3!H$2, Sheet1!$M:$M, $C4, Sheet1!$L:$L, Sheet2!$A$6)+COUNTIFS(Sheet1!$B:$B, Sheet3!H$2, Sheet1!$M:$M, $C4, Sheet1!$L:$L, Sheet2!$A$7)+COUNTIFS(Sheet1!$B:$B, Sheet3!H$2, Sheet1!$M:$M, $C4, Sheet1!$L:$L, Sheet2!$A$9) -> 0 | I4: =COUNTIFS(Sheet1!$B:$B, Sheet3!H$2, Sheet1!$M:$M, $C4, Sheet1!$L:$L, Sheet2!$A$6)+COUNTIFS(Sheet1!$B:$B, Sheet3!H$2, Sheet1!$M:$M, $C4, Sheet1!$L:$L, Sheet2!$A$7) -> 0 | J4: =COUNTIFS(Sheet1!$B:$B, Sheet3!J$2, Sheet1!$M:$M, $C4, Sheet1!$L:$L, Sheet2!$A$6)+COUNTIFS(Sheet1!$B:$B, Sheet3!J$2, Sheet1!$M:$M, $C4, Sheet1!$L:$L, Sheet2!$A$7)+COUNTIFS(Sheet1!$B:$B, Sheet3!J$2, Sheet1!$M:$M, $C4, Sheet1!$L:$L, Sheet2!$A$9) -> 0 | K4: =COUNTIFS(Sheet1!$B:$B, Sheet3!J$2, Sheet1!$M:$M, $C4, Sheet1!$L:$L, Sheet2!$A$6)+COUNTIFS(Sheet1!$B:$B, Sheet3!J$2, Sheet1!$M:$M, $C4, Sheet1!$L:$L, Sheet2!$A$7) -> 0 | L4: =COUNTIFS(Sheet1!$B:$B, Sheet3!L$2, Sheet1!$M:$M, $C4, Sheet1!$L:$L, Sheet2!$A$6)+COUNTIFS(Sheet1!$B:$B, Sheet3!L$2, Sheet1!$M:$M, $C4, Sheet1!$L:$L, Sheet2!$A$7)+COUNTIFS(Sheet1!$B:$B, Sheet3!L$2, Sheet1!$M:$M, $C4, Sheet1!$L:$L, Sheet2!$A$9) -> 0 | M4: =COUNTIFS(Sheet1!$B:$B, Sheet3!L$2, Sheet1!$M:$M, $C4, Sheet1!$L:$L, Sheet2!$A$6)+COUNTIFS(Sheet1!$B:$B, Sheet3!L$2, Sheet1!$M:$M, $C4, Sheet1!$L:$L, Sheet2!$A$7) -> 0 | N4: =COUNTIFS(Sheet1!$B:$B, Sheet3!N$2, Sheet1!$M:$M, $C4, Sheet1!$L:$L, Sheet2!$A$6)+COUNTIFS(Sheet1!$B:$B, Sheet3!N$2, Sheet1!$M:$M, $C4, Sheet1!$L:$L, Sheet2!$A$7)+COUNTIFS(Sheet1!$B:$B, Sheet3!N$2, Sheet1!$M:$M, $C4, Sheet1!$L:$L, Sheet2!$A$9) -> 0 | O4: =COUNTIFS(Sheet1!$B:$B, Sheet3!N$2, Sheet1!$M:$M, $C4, Sheet1!$L:$L, Sheet2!$A$6)+COUNTIFS(Sheet1!$B:$B, Sheet3!N$2, Sheet1!$M:$M, $C4, Sheet1!$L:$L, Sheet2!$A$7) -> 0 | P4: =COUNTIFS(Sheet1!$B:$B, Sheet3!P$2, Sheet1!$M:$M, $C4, Sheet1!$L:$L, Sheet2!$A$6)+COUNTIFS(Sheet1!$B:$B, Sheet3!P$2, Sheet1!$M:$M, $C4, Sheet1!$L:$L, Sheet2!$A$7)+COUNTIFS(Sheet1!$B:$B, Sheet3!P$2, Sheet1!$M:$M, $C4, Sheet1!$L:$L, Sheet2!$A$9) -> 0 | Q4: =COUNTIFS(Sheet1!$B:$B, Sheet3!P$2, Sheet1!$M:$M, $C4, Sheet1!$L:$L, Sheet2!$A$6)+COUNTIFS(Sheet1!$B:$B, Sheet3!P$2, Sheet1!$M:$M, $C4, Sheet1!$L:$L, Sheet2!$A$7) -> 0 | R4: =COUNTIFS(Sheet1!$B:$B, Sheet3!R$2, Sheet1!$M:$M, $C4, Sheet1!$L:$L, Sheet2!$A$6)+COUNTIFS(Sheet1!$B:$B, Sheet3!R$2, Sheet1!$M:$M, $C4, Sheet1!$L:$L, Sheet2!$A$7)+COUNTIFS(Sheet1!$B:$B, Sheet3!R$2, Sheet1!$M:$M, $C4, Sheet1!$L:$L, Sheet2!$A$9) -> 0 | S4: =COUNTIFS(Sheet1!$B:$B, Sheet3!R$2, Sheet1!$M:$M, $C4, Sheet1!$L:$L, Sheet2!$A$6)+COUNTIFS(Sheet1!$B:$B, Sheet3!R$2, Sheet1!$M:$M, $C4, Sheet1!$L:$L, Sheet2!$A$7) -> 0 | T4: =COUNTIFS(Sheet1!$B:$B, Sheet3!T$2, Sheet1!$M:$M, $C4, Sheet1!$L:$L, Sheet2!$A$6)+COUNTIFS(Sheet1!$B:$B, Sheet3!T$2, Sheet1!$M:$M, $C4, Sheet1!$L:$L, Sheet2!$A$7)+COUNTIFS(Sheet1!$B:$B, Sheet3!T$2, Sheet1!$M:$M, $C4, Sheet1!$L:$L, Sheet2!$A$9) -> 0 | U4: =COUNTIFS(Sheet1!$B:$B, Sheet3!T$2, Sheet1!$M:$M, $C4, Sheet1!$L:$L, Sheet2!$A$6)+COUNTIFS(Sheet1!$B:$B, Sheet3!T$2, Sheet1!$M:$M, $C4, Sheet1!$L:$L, Sheet2!$A$7) -> 0 | V4: =COUNTIFS(Sheet1!$B:$B, Sheet3!V$2, Sheet1!$M:$M, $C4, Sheet1!$L:$L, Sheet2!$A$6)+COUNTIFS(Sheet1!$B:$B, Sheet3!V$2, Sheet1!$M:$M, $C4, Sheet1!$L:$L, Sheet2!$A$7)+COUNTIFS(Sheet1!$B:$B, Sheet3!V$2, Sheet1!$M:$M, $C4, Sheet1!$L:$L, Sheet2!$A$9) -> 0 | W4: =COUNTIFS(Sheet1!$B:$B, Sheet3!V$2, Sheet1!$M:$M, $C4, Sheet1!$L:$L, Sheet2!$A$6)+COUNTIFS(Sheet1!$B:$B, Sheet3!V$2, Sheet1!$M:$M, $C4, Sheet1!$L:$L, Sheet2!$A$7) -> 0 | X4: =COUNTIFS(Sheet1!$B:$B, Sheet3!X$2, Sheet1!$M:$M, $C4, Sheet1!$L:$L, Sheet2!$A$6)+COUNTIFS(Sheet1!$B:$B, Sheet3!X$2, Sheet1!$M:$M, $C4, Sheet1!$L:$L, Sheet2!$A$7)+COUNTIFS(Sheet1!$B:$B, Sheet3!X$2, Sheet1!$M:$M, $C4, Sheet1!$L:$L, Sheet2!$A$9) -> 0 | Y4: =COUNTIFS(Sheet1!$B:$B, Sheet3!X$2, Sheet1!$M:$M, $C4, Sheet1!$L:$L, Sheet2!$A$6)+COUNTIFS(Sheet1!$B:$B, Sheet3!X$2, Sheet1!$M:$M, $C4, Sheet1!$L:$L, Sheet2!$A$7) -> 0 | Z4: =COUNTIFS(Sheet1!$B:$B, Sheet3!Z$2, Sheet1!$M:$M, $C4, Sheet1!$L:$L, Sheet2!$A$6)+COUNTIFS(Sheet1!$B:$B, Sheet3!Z$2, Sheet1!$M:$M, $C4, Sheet1!$L:$L, Sheet2!$A$7)+COUNTIFS(Sheet1!$B:$B, Sheet3!Z$2, Sheet1!$M:$M, $C4, Sheet1!$L:$L, Sheet2!$A$9) -> 0 | AA4: =COUNTIFS(Sheet1!$B:$B, Sheet3!Z$2, Sheet1!$M:$M, $C4, Sheet1!$L:$L, Sheet2!$A$6)+COUNTIFS(Sheet1!$B:$B, Sheet3!Z$2, Sheet1!$M:$M, $C4, Sheet1!$L:$L, Sheet2!$A$7) -> 0 | AB4: =COUNTIFS(Sheet1!$B:$B, Sheet3!AB$2, Sheet1!$M:$M, $C4, Sheet1!$L:$L, Sheet2!$A$6)+COUNTIFS(Sheet1!$B:$B, Sheet3!AB$2, Sheet1!$M:$M, $C4, Sheet1!$L:$L, Sheet2!$A$7)+COUNTIFS(Sheet1!$B:$B, Sheet3!AB$2, Sheet1!$M:$M, $C4, Sheet1!$L:$L, Sheet2!$A$9) -> 2 | AC4: =COUNTIFS(Sheet1!$B:$B, Sheet3!AB$2, Sheet1!$M:$M, $C4, Sheet1!$L:$L, Sheet2!$A$6)+COUNTIFS(Sheet1!$B:$B, Sheet3!AB$2, Sheet1!$M:$M, $C4, Sheet1!$L:$L, Sheet2!$A$7) -> 1 | AD4: =COUNTIFS(Sheet1!$B:$B, Sheet3!AD$2, Sheet1!$M:$M, $C4, Sheet1!$L:$L, Sheet2!$A$6)+COUNTIFS(Sheet1!$B:$B, Sheet3!AD$2, Sheet1!$M:$M, $C4, Sheet1!$L:$L, Sheet2!$A$7)+COUNTIFS(Sheet1!$B:$B, Sheet3!AD$2, Sheet1!$M:$M, $C4, Sheet1!$L:$L, Sheet2!$A$9) -> 5 | AE4: =COUNTIFS(Sheet1!$B:$B, Sheet3!AD$2, Sheet1!$M:$M, $C4, Sheet1!$L:$L, Sheet2!$A$6)+COUNTIFS(Sheet1!$B:$B, Sheet3!AD$2, Sheet1!$M:$M, $C4, Sheet1!$L:$L, Sheet2!$A$7) -> 0 | AF4: =COUNTIFS(Sheet1!$B:$B, Sheet3!AF$2, Sheet1!$M:$M, $C4, Sheet1!$L:$L, Sheet2!$A$6)+COUNTIFS(Sheet1!$B:$B, Sheet3!AF$2, Sheet1!$M:$M, $C4, Sheet1!$L:$L, Sheet2!$A$7)+COUNTIFS(Sheet1!$B:$B, Sheet3!AF$2, Sheet1!$M:$M, $C4, Sheet1!$L:$L, Sheet2!$A$9) -> 6 | AG4: =COUNTIFS(Sheet1!$B:$B, Sheet3!AF$2, Sheet1!$M:$M, $C4, Sheet1!$L:$L, Sheet2!$A$6)+COUNTIFS(Sheet1!$B:$B, Sheet3!AF$2, Sheet1!$M:$M, $C4, Sheet1!$L:$L, Sheet2!$A$7) -> 6 | AH4: =COUNTIFS(Sheet1!$B:$B, Sheet3!AH$2, Sheet1!$M:$M, $C4, Sheet1!$L:$L, Sheet2!$A$6)+COUNTIFS(Sheet1!$B:$B, Sheet3!AH$2, Sheet1!$M:$M, $C4, Sheet1!$L:$L, Sheet2!$A$7)+COUNTIFS(Sheet1!$B:$B, Sheet3!AH$2, Sheet1!$M:$M, $C4, Sheet1!$L:$L, Sheet2!$A$9) -> 0 | AI4: =COUNTIFS(Sheet1!$B:$B, Sheet3!AH$2, Sheet1!$M:$M, $C4, Sheet1!$L:$L, Sheet2!$A$6)+COUNTIFS(Sheet1!$B:$B, Sheet3!AH$2, Sheet1!$M:$M, $C4, Sheet1!$L:$L, Sheet2!$A$7) -> 0 | AJ4: =COUNTIFS(Sheet1!$B:$B, Sheet3!AJ$2, Sheet1!$M:$M, $C4, Sheet1!$L:$L, Sheet2!$A$6)+COUNTIFS(Sheet1!$B:$B, Sheet3!AJ$2, Sheet1!$M:$M, $C4, Sheet1!$L:$L, Sheet2!$A$7)+COUNTIFS(Sheet1!$B:$B, Sheet3!AJ$2, Sheet1!$M:$M, $C4, Sheet1!$L:$L, Sheet2!$A$9) -> 0 | AK4: =COUNTIFS(Sheet1!$B:$B, Sheet3!AJ$2, Sheet1!$M:$M, $C4, Sheet1!$L:$L, Sheet2!$A$6)+COUNTIFS(Sheet1!$B:$B, Sheet3!AJ$2, Sheet1!$M:$M, $C4, Sheet1!$L:$L, Sheet2!$A$7) -> 0 | AL4: =COUNTIFS(Sheet1!$B:$B, Sheet3!AL$2, Sheet1!$M:$M, $C4, Sheet1!$L:$L, Sheet2!$A$6)+COUNTIFS(Sheet1!$B:$B, Sheet3!AL$2, Sheet1!$M:$M, $C4, Sheet1!$L:$L, Sheet2!$A$7)+COUNTIFS(Sheet1!$B:$B, Sheet3!AL$2, Sheet1!$M:$M, $C4, Sheet1!$L:$L, Sheet2!$A$9) -> 0 | AM4: =COUNTIFS(Sheet1!$B:$B, Sheet3!AL$2, Sheet1!$M:$M, $C4, Sheet1!$L:$L, Sheet2!$A$6)+COUNTIFS(Sheet1!$B:$B, Sheet3!AL$2, Sheet1!$M:$M, $C4, Sheet1!$L:$L, Sheet2!$A$7) -> 0 | AN4: =COUNTIFS(Sheet1!$B:$B, Sheet3!AN$2, Sheet1!$M:$M, $C4, Sheet1!$L:$L, Sheet2!$A$6)+COUNTIFS(Sheet1!$B:$B, Sheet3!AN$2, Sheet1!$M:$M, $C4, Sheet1!$L:$L, Sheet2!$A$7)+COUNTIFS(Sheet1!$B:$B, Sheet3!AN$2, Sheet1!$M:$M, $C4, Sheet1!$L:$L, Sheet2!$A$9) -> 0 | AO4: =COUNTIFS(Sheet1!$B:$B, Sheet3!AN$2, Sheet1!$M:$M, $C4, Sheet1!$L:$L, Sheet2!$A$6)+COUNTIFS(Sheet1!$B:$B, Sheet3!AN$2, Sheet1!$M:$M, $C4, Sheet1!$L:$L, Sheet2!$A$7) -> 0 | AP4: =COUNTIFS(Sheet1!$B:$B, Sheet3!AP$2, Sheet1!$M:$M, $C4, Sheet1!$L:$L, Sheet2!$A$6)+COUNTIFS(Sheet1!$B:$B, Sheet3!AP$2, Sheet1!$M:$M, $C4, Sheet1!$L:$L, Sheet2!$A$7)+COUNTIFS(Sheet1!$B:$B, Sheet3!AP$2, Sheet1!$M:$M, $C4, Sheet1!$L:$L, Sheet2!$A$9) -> 0 | AQ4: =COUNTIFS(Sheet1!$B:$B, Sheet3!AP$2, Sheet1!$M:$M, $C4, Sheet1!$L:$L, Sheet2!$A$6)+COUNTIFS(Sheet1!$B:$B, Sheet3!AP$2, Sheet1!$M:$M, $C4, Sheet1!$L:$L, Sheet2!$A$7) -> 0 | AR4: =COUNTIFS(Sheet1!$B:$B, Sheet3!AR$2, Sheet1!$M:$M, $C4, Sheet1!$L:$L, Sheet2!$A$6)+COUNTIFS(Sheet1!$B:$B, Sheet3!AR$2, Sheet1!$M:$M, $C4, Sheet1!$L:$L, Sheet2!$A$7)+COUNTIFS(Sheet1!$B:$B, Sheet3!AR$2, Sheet1!$M:$M, $C4, Sheet1!$L:$L, Sheet2!$A$9) -> 0 | AS4: =COUNTIFS(Sheet1!$B:$B, Sheet3!AR$2, Sheet1!$M:$M, $C4, Sheet1!$L:$L, Sheet2!$A$6)+COUNTIFS(Sheet1!$B:$B, Sheet3!AR$2, Sheet1!$M:$M, $C4, Sheet1!$L:$L, Sheet2!$A$7) -> 0 | AT4: =COUNTIFS(Sheet1!$B:$B, Sheet3!AT$2, Sheet1!$M:$M, $C4, Sheet1!$L:$L, Sheet2!$A$6)+COUNTIFS(Sheet1!$B:$B, Sheet3!AT$2, Sheet1!$M:$M, $C4, Sheet1!$L:$L, Sheet2!$A$7)+COUNTIFS(Sheet1!$B:$B, Sheet3!AT$2, Sheet1!$M:$M, $C4, Sheet1!$L:$L, Sheet2!$A$9) -> 0 | AU4: =COUNTIFS(Sheet1!$B:$B, Sheet3!AT$2, Sheet1!$M:$M, $C4, Sheet1!$L:$L, Sheet2!$A$6)+COUNTIFS(Sheet1!$B:$B, Sheet3!AT$2, Sheet1!$M:$M, $C4, Sheet1!$L:$L, Sheet2!$A$7) -> 0 | AV4: =COUNTIFS(Sheet1!$B:$B, Sheet3!AV$2, Sheet1!$M:$M, $C4, Sheet1!$L:$L, Sheet2!$A$6)+COUNTIFS(Sheet1!$B:$B, Sheet3!AV$2, Sheet1!$M:$M, $C4, Sheet1!$L:$L, Sheet2!$A$7)+COUNTIFS(Sheet1!$B:$B, Sheet3!AV$2, Sheet1!$M:$M, $C4, Sheet1!$L:$L, Sheet2!$A$9) -> 0 | AW4: =COUNTIFS(Sheet1!$B:$B, Sheet3!AV$2, Sheet1!$M:$M, $C4, Sheet1!$L:$L, Sheet2!$A$6)+COUNTIFS(Sheet1!$B:$B, Sheet3!AV$2, Sheet1!$M:$M, $C4, Sheet1!$L:$L, Sheet2!$A$7) -> 0
A5: MONCR | B5: APU1 | C5: MONCR | D5: =COUNTIFS(Sheet1!$B:$B, Sheet3!D$2, Sheet1!$M:$M, $C5, Sheet1!$L:$L, Sheet2!$A$6)+COUNTIFS(Sheet1!$B:$B, Sheet3!D$2, Sheet1!$M:$M, $C5, Sheet1!$L:$L, Sheet2!$A$7)+COUNTIFS(Sheet1!$B:$B, Sheet3!D$2, Sheet1!$M:$M, $C5, Sheet1!$L:$L, Sheet2!$A$9) -> 0 | E5: =COUNTIFS(Sheet1!$B:$B, Sheet3!D$2, Sheet1!$M:$M, $C5, Sheet1!$L:$L, Sheet2!$A$6)+COUNTIFS(Sheet1!$B:$B, Sheet3!D$2, Sheet1!$M:$M, $C5, Sheet1!$L:$L, Sheet2!$A$7) -> 0 | F5: =COUNTIFS(Sheet1!$B:$B, Sheet3!F$2, Sheet1!$M:$M, $C5, Sheet1!$L:$L, Sheet2!$A$6)+COUNTIFS(Sheet1!$B:$B, Sheet3!F$2, Sheet1!$M:$M, $C5, Sheet1!$L:$L, Sheet2!$A$7)+COUNTIFS(Sheet1!$B:$B, Sheet3!F$2, Sheet1!$M:$M, $C5, Sheet1!$L:$L, Sheet2!$A$9) -> 0 | G5: =COUNTIFS(Sheet1!$B:$B, Sheet3!F$2, Sheet1!$M:$M, $C5, Sheet1!$L:$L, Sheet2!$A$6)+COUNTIFS(Sheet1!$B:$B, Sheet3!F$2, Sheet1!$M:$M, $C5, Sheet1!$L:$L, Sheet2!$A$7) -> 0 | H5: =COUNTIFS(Sheet1!$B:$B, Sheet3!H$2, Sheet1!$M:$M, $C5, Sheet1!$L:$L, Sheet2!$A$6)+COUNTIFS(Sheet1!$B:$B, Sheet3!H$2, Sheet1!$M:$M, $C5, Sheet1!$L:$L, Sheet2!$A$7)+COUNTIFS(Sheet1!$B:$B, Sheet3!H$2, Sheet1!$M:$M, $C5, Sheet1!$L:$L, Sheet2!$A$9) -> 0 | I5: =COUNTIFS(Sheet1!$B:$B, Sheet3!H$2, Sheet1!$M:$M, $C5, Sheet1!$L:$L, Sheet2!$A$6)+COUNTIFS(Sheet1!$B:$B, Sheet3!H$2, Sheet1!$M:$M, $C5, Sheet1!$L:$L, Sheet2!$A$7) -> 0 | J5: =COUNTIFS(Sheet1!$B:$B, Sheet3!J$2, Sheet1!$M:$M, $C5, Sheet1!$L:$L, Sheet2!$A$6)+COUNTIFS(Sheet1!$B:$B, Sheet3!J$2, Sheet1!$M:$M, $C5, Sheet1!$L:$L, Sheet2!$A$7)+COUNTIFS(Sheet1!$B:$B, Sheet3!J$2, Sheet1!$M:$M, $C5, Sheet1!$L:$L, Sheet2!$A$9) -> 0 | K5: =COUNTIFS(Sheet1!$B:$B, Sheet3!J$2, Sheet1!$M:$M, $C5, Sheet1!$L:$L, Sheet2!$A$6)+COUNTIFS(Sheet1!$B:$B, Sheet3!J$2, Sheet1!$M:$M, $C5, Sheet1!$L:$L, Sheet2!$A$7) -> 0 | L5: =COUNTIFS(Sheet1!$B:$B, Sheet3!L$2, Sheet1!$M:$M, $C5, Sheet1!$L:$L, Sheet2!$A$6)+COUNTIFS(Sheet1!$B:$B, Sheet3!L$2, Sheet1!$M:$M, $C5, Sheet1!$L:$L, Sheet2!$A$7)+COUNTIFS(Sheet1!$B:$B, Sheet3!L$2, Sheet1!$M:$M, $C5, Sheet1!$L:$L, Sheet2!$A$9) -> 0 | M5: =COUNTIFS(Sheet1!$B:$B, Sheet3!L$2, Sheet1!$M:$M, $C5, Sheet1!$L:$L, Sheet2!$A$6)+COUNTIFS(Sheet1!$B:$B, Sheet3!L$2, Sheet1!$M:$M, $C5, Sheet1!$L:$L, Sheet2!$A$7) -> 0 | N5: =COUNTIFS(Sheet1!$B:$B, Sheet3!N$2, Sheet1!$M:$M, $C5, Sheet1!$L:$L, Sheet2!$A$6)+COUNTIFS(Sheet1!$B:$B, Sheet3!N$2, Sheet1!$M:$M, $C5, Sheet1!$L:$L, Sheet2!$A$7)+COUNTIFS(Sheet1!$B:$B, Sheet3!N$2, Sheet1!$M:$M, $C5, Sheet1!$L:$L, Sheet2!$A$9) -> 0 | O5: =COUNTIFS(Sheet1!$B:$B, Sheet3!N$2, Sheet1!$M:$M, $C5, Sheet1!$L:$L, Sheet2!$A$6)+COUNTIFS(Sheet1!$B:$B, Sheet3!N$2, Sheet1!$M:$M, $C5, Sheet1!$L:$L, Sheet2!$A$7) -> 0 | P5: =COUNTIFS(Sheet1!$B:$B, Sheet3!P$2, Sheet1!$M:$M, $C5, Sheet1!$L:$L, Sheet2!$A$6)+COUNTIFS(Sheet1!$B:$B, Sheet3!P$2, Sheet1!$M:$M, $C5, Sheet1!$L:$L, Sheet2!$A$7)+COUNTIFS(Sheet1!$B:$B, Sheet3!P$2, Sheet1!$M:$M, $C5, Sheet1!$L:$L, Sheet2!$A$9) -> 0 | Q5: =COUNTIFS(Sheet1!$B:$B, Sheet3!P$2, Sheet1!$M:$M, $C5, Sheet1!$L:$L, Sheet2!$A$6)+COUNTIFS(Sheet1!$B:$B, Sheet3!P$2, Sheet1!$M:$M, $C5, Sheet1!$L:$L, Sheet2!$A$7) -> 0 | R5: =COUNTIFS(Sheet1!$B:$B, Sheet3!R$2, Sheet1!$M:$M, $C5, Sheet1!$L:$L, Sheet2!$A$6)+COUNTIFS(Sheet1!$B:$B, Sheet3!R$2, Sheet1!$M:$M, $C5, Sheet1!$L:$L, Sheet2!$A$7)+COUNTIFS(Sheet1!$B:$B, Sheet3!R$2, Sheet1!$M:$M, $C5, Sheet1!$L:$L, Sheet2!$A$9) -> 0 | S5: =COUNTIFS(Sheet1!$B:$B, Sheet3!R$2, Sheet1!$M:$M, $C5, Sheet1!$L:$L, Sheet2!$A$6)+COUNTIFS(Sheet1!$B:$B, Sheet3!R$2, Sheet1!$M:$M, $C5, Sheet1!$L:$L, Sheet2!$A$7) -> 0 | T5: =COUNTIFS(Sheet1!$B:$B, Sheet3!T$2, Sheet1!$M:$M, $C5, Sheet1!$L:$L, Sheet2!$A$6)+COUNTIFS(Sheet1!$B:$B, Sheet3!T$2, Sheet1!$M:$M, $C5, Sheet1!$L:$L, Sheet2!$A$7)+COUNTIFS(Sheet1!$B:$B, Sheet3!T$2, Sheet1!$M:$M, $C5, Sheet1!$L:$L, Sheet2!$A$9) -> 0 | U5: =COUNTIFS(Sheet1!$B:$B, Sheet3!T$2, Sheet1!$M:$M, $C5, Sheet1!$L:$L, Sheet2!$A$6)+COUNTIFS(Sheet1!$B:$B, Sheet3!T$2, Sheet1!$M:$M, $C5, Sheet1!$L:$L, Sheet2!$A$7) -> 0 | V5: =COUNTIFS(Sheet1!$B:$B, Sheet3!V$2, Sheet1!$M:$M, $C5, Sheet1!$L:$L, Sheet2!$A$6)+COUNTIFS(Sheet1!$B:$B, Sheet3!V$2, Sheet1!$M:$M, $C5, Sheet1!$L:$L, Sheet2!$A$7)+COUNTIFS(Sheet1!$B:$B, Sheet3!V$2, Sheet1!$M:$M, $C5, Sheet1!$L:$L, Sheet2!$A$9) -> 0 | W5: =COUNTIFS(Sheet1!$B:$B, Sheet3!V$2, Sheet1!$M:$M, $C5, Sheet1!$L:$L, Sheet2!$A$6)+COUNTIFS(Sheet1!$B:$B, Sheet3!V$2, Sheet1!$M:$M, $C5, Sheet1!$L:$L, Sheet2!$A$7) -> 0 | X5: =COUNTIFS(Sheet1!$B:$B, Sheet3!X$2, Sheet1!$M:$M, $C5, Sheet1!$L:$L, Sheet2!$A$6)+COUNTIFS(Sheet1!$B:$B, Sheet3!X$2, Sheet1!$M:$M, $C5, Sheet1!$L:$L, Sheet2!$A$7)+COUNTIFS(Sheet1!$B:$B, Sheet3!X$2, Sheet1!$M:$M, $C5, Sheet1!$L:$L, Sheet2!$A$9) -> 0 | Y5: =COUNTIFS(Sheet1!$B:$B, Sheet3!X$2, Sheet1!$M:$M, $C5, Sheet1!$L:$L, Sheet2!$A$6)+COUNTIFS(Sheet1!$B:$B, Sheet3!X$2, Sheet1!$M:$M, $C5, Sheet1!$L:$L, Sheet2!$A$7) -> 0 | Z5: =COUNTIFS(Sheet1!$B:$B, Sheet3!Z$2, Sheet1!$M:$M, $C5, Sheet1!$L:$L, Sheet2!$A$6)+COUNTIFS(Sheet1!$B:$B, Sheet3!Z$2, Sheet1!$M:$M, $C5, Sheet1!$L:$L, Sheet2!$A$7)+COUNTIFS(Sheet1!$B:$B, Sheet3!Z$2, Sheet1!$M:$M, $C5, Sheet1!$L:$L, Sheet2!$A$9) -> 0 | AA5: =COUNTIFS(Sheet1!$B:$B, Sheet3!Z$2, Sheet1!$M:$M, $C5, Sheet1!$L:$L, Sheet2!$A$6)+COUNTIFS(Sheet1!$B:$B, Sheet3!Z$2, Sheet1!$M:$M, $C5, Sheet1!$L:$L, Sheet2!$A$7) -> 0 | AB5: =COUNTIFS(Sheet1!$B:$B, Sheet3!AB$2, Sheet1!$M:$M, $C5, Sheet1!$L:$L, Sheet2!$A$6)+COUNTIFS(Sheet1!$B:$B, Sheet3!AB$2, Sheet1!$M:$M, $C5, Sheet1!$L:$L, Sheet2!$A$7)+COUNTIFS(Sheet1!$B:$B, Sheet3!AB$2, Sheet1!$M:$M, $C5, Sheet1!$L:$L, Sheet2!$A$9) -> 1 | AC5: =COUNTIFS(Sheet1!$B:$B, Sheet3!AB$2, Sheet1!$M:$M, $C5, Sheet1!$L:$L, Sheet2!$A$6)+COUNTIFS(Sheet1!$B:$B, Sheet3!AB$2, Sheet1!$M:$M, $C5, Sheet1!$L:$L, Sheet2!$A$7) -> 1 | AD5: =COUNTIFS(Sheet1!$B:$B, Sheet3!AD$2, Sheet1!$M:$M, $C5, Sheet1!$L:$L, Sheet2!$A$6)+COUNTIFS(Sheet1!$B:$B, Sheet3!AD$2, Sheet1!$M:$M, $C5, Sheet1!$L:$L, Sheet2!$A$7)+COUNTIFS(Sheet1!$B:$B, Sheet3!AD$2, Sheet1!$M:$M, $C5, Sheet1!$L:$L, Sheet2!$A$9) -> 2 | AE5: =COUNTIFS(Sheet1!$B:$B, Sheet3!AD$2, Sheet1!$M:$M, $C5, Sheet1!$L:$L, Sheet2!$A$6)+COUNTIFS(Sheet1!$B:$B, Sheet3!AD$2, Sheet1!$M:$M, $C5, Sheet1!$L:$L, Sheet2!$A$7) -> 2 | AF5: =COUNTIFS(Sheet1!$B:$B, Sheet3!AF$2, Sheet1!$M:$M, $C5, Sheet1!$L:$L, Sheet2!$A$6)+COUNTIFS(Sheet1!$B:$B, Sheet3!AF$2, Sheet1!$M:$M, $C5, Sheet1!$L:$L, Sheet2!$A$7)+COUNTIFS(Sheet1!$B:$B, Sheet3!AF$2, Sheet1!$M:$M, $C5, Sheet1!$L:$L, Sheet2!$A$9) -> 1 | AG5: =COUNTIFS(Sheet1!$B:$B, Sheet3!AF$2, Sheet1!$M:$M, $C5, Sheet1!$L:$L, Sheet2!$A$6)+COUNTIFS(Sheet1!$B:$B, Sheet3!AF$2, Sheet1!$M:$M, $C5, Sheet1!$L:$L, Sheet2!$A$7) -> 1 | AH5: =COUNTIFS(Sheet1!$B:$B, Sheet3!AH$2, Sheet1!$M:$M, $C5, Sheet1!$L:$L, Sheet2!$A$6)+COUNTIFS(Sheet1!$B:$B, Sheet3!AH$2, Sheet1!$M:$M, $C5, Sheet1!$L:$L, Sheet2!$A$7)+COUNTIFS(Sheet1!$B:$B, Sheet3!AH$2, Sheet1!$M:$M, $C5, Sheet1!$L:$L, Sheet2!$A$9) -> 0 | AI5: =COUNTIFS(Sheet1!$B:$B, Sheet3!AH$2, Sheet1!$M:$M, $C5, Sheet1!$L:$L, Sheet2!$A$6)+COUNTIFS(Sheet1!$B:$B, Sheet3!AH$2, Sheet1!$M:$M, $C5, Sheet1!$L:$L, Sheet2!$A$7) -> 0 | AJ5: =COUNTIFS(Sheet1!$B:$B, Sheet3!AJ$2, Sheet1!$M:$M, $C5, Sheet1!$L:$L, Sheet2!$A$6)+COUNTIFS(Sheet1!$B:$B, Sheet3!AJ$2, Sheet1!$M:$M, $C5, Sheet1!$L:$L, Sheet2!$A$7)+COUNTIFS(Sheet1!$B:$B, Sheet3!AJ$2, Sheet1!$M:$M, $C5, Sheet1!$L:$L, Sheet2!$A$9) -> 0 | AK5: =COUNTIFS(Sheet1!$B:$B, Sheet3!AJ$2, Sheet1!$M:$M, $C5, Sheet1!$L:$L, Sheet2!$A$6)+COUNTIFS(Sheet1!$B:$B, Sheet3!AJ$2, Sheet1!$M:$M, $C5, Sheet1!$L:$L, Sheet2!$A$7) -> 0 | AL5: =COUNTIFS(Sheet1!$B:$B, Sheet3!AL$2, Sheet1!$M:$M, $C5, Sheet1!$L:$L, Sheet2!$A$6)+COUNTIFS(Sheet1!$B:$B, Sheet3!AL$2, Sheet1!$M:$M, $C5, Sheet1!$L:$L, Sheet2!$A$7)+COUNTIFS(Sheet1!$B:$B, Sheet3!AL$2, Sheet1!$M:$M, $C5, Sheet1!$L:$L, Sheet2!$A$9) -> 0 | AM5: =COUNTIFS(Sheet1!$B:$B, Sheet3!AL$2, Sheet1!$M:$M, $C5, Sheet1!$L:$L, Sheet2!$A$6)+COUNTIFS(Sheet1!$B:$B, Sheet3!AL$2, Sheet1!$M:$M, $C5, Sheet1!$L:$L, Sheet2!$A$7) -> 0 | AN5: =COUNTIFS(Sheet1!$B:$B, Sheet3!AN$2, Sheet1!$M:$M, $C5, Sheet1!$L:$L, Sheet2!$A$6)+COUNTIFS(Sheet1!$B:$B, Sheet3!AN$2, Sheet1!$M:$M, $C5, Sheet1!$L:$L, Sheet2!$A$7)+COUNTIFS(Sheet1!$B:$B, Sheet3!AN$2, Sheet1!$M:$M, $C5, Sheet1!$L:$L, Sheet2!$A$9) -> 0 | AO5: =COUNTIFS(Sheet1!$B:$B, Sheet3!AN$2, Sheet1!$M:$M, $C5, Sheet1!$L:$L, Sheet2!$A$6)+COUNTIFS(Sheet1!$B:$B, Sheet3!AN$2, Sheet1!$M:$M, $C5, Sheet1!$L:$L, Sheet2!$A$7) -> 0 | AP5: =COUNTIFS(Sheet1!$B:$B, Sheet3!AP$2, Sheet1!$M:$M, $C5, Sheet1!$L:$L, Sheet2!$A$6)+COUNTIFS(Sheet1!$B:$B, Sheet3!AP$2, Sheet1!$M:$M, $C5, Sheet1!$L:$L, Sheet2!$A$7)+COUNTIFS(Sheet1!$B:$B, Sheet3!AP$2, Sheet1!$M:$M, $C5, Sheet1!$L:$L, Sheet2!$A$9) -> 0 | AQ5: =COUNTIFS(Sheet1!$B:$B, Sheet3!AP$2, Sheet1!$M:$M, $C5, Sheet1!$L:$L, Sheet2!$A$6)+COUNTIFS(Sheet1!$B:$B, Sheet3!AP$2, Sheet1!$M:$M, $C5, Sheet1!$L:$L, Sheet2!$A$7) -> 0 | AR5: =COUNTIFS(Sheet1!$B:$B, Sheet3!AR$2, Sheet1!$M:$M, $C5, Sheet1!$L:$L, Sheet2!$A$6)+COUNTIFS(Sheet1!$B:$B, Sheet3!AR$2, Sheet1!$M:$M, $C5, Sheet1!$L:$L, Sheet2!$A$7)+COUNTIFS(Sheet1!$B:$B, Sheet3!AR$2, Sheet1!$M:$M, $C5, Sheet1!$L:$L, Sheet2!$A$9) -> 0 | AS5: =COUNTIFS(Sheet1!$B:$B, Sheet3!AR$2, Sheet1!$M:$M, $C5, Sheet1!$L:$L, Sheet2!$A$6)+COUNTIFS(Sheet1!$B:$B, Sheet3!AR$2, Sheet1!$M:$M, $C5, Sheet1!$L:$L, Sheet2!$A$7) -> 0 | AT5: =COUNTIFS(Sheet1!$B:$B, Sheet3!AT$2, Sheet1!$M:$M, $C5, Sheet1!$L:$L, Sheet2!$A$6)+COUNTIFS(Sheet1!$B:$B, Sheet3!AT$2, Sheet1!$M:$M, $C5, Sheet1!$L:$L, Sheet2!$A$7)+COUNTIFS(Sheet1!$B:$B, Sheet3!AT$2, Sheet1!$M:$M, $C5, Sheet1!$L:$L, Sheet2!$A$9) -> 0 | AU5: =COUNTIFS(Sheet1!$B:$B, Sheet3!AT$2, Sheet1!$M:$M, $C5, Sheet1!$L:$L, Sheet2!$A$6)+COUNTIFS(Sheet1!$B:$B, Sheet3!AT$2, Sheet1!$M:$M, $C5, Sheet1!$L:$L, Sheet2!$A$7) -> 0 | AV5: =COUNTIFS(Sheet1!$B:$B, Sheet3!AV$2, Sheet1!$M:$M, $C5, Sheet1!$L:$L, Sheet2!$A$6)+COUNTIFS(Sheet1!$B:$B, Sheet3!AV$2, Sheet1!$M:$M, $C5, Sheet1!$L:$L, Sheet2!$A$7)+COUNTIFS(Sheet1!$B:$B, Sheet3!AV$2, Sheet1!$M:$M, $C5, Sheet1!$L:$L, Sheet2!$A$9) -> 0 | AW5: =COUNTIFS(Sheet1!$B:$B, Sheet3!AV$2, Sheet1!$M:$M, $C5, Sheet1!$L:$L, Sheet2!$A$6)+COUNTIFS(Sheet1!$B:$B, Sheet3!AV$2, Sheet1!$M:$M, $C5, Sheet1!$L:$L, Sheet2!$A$7) -> 0
